2019-05-26 15:08:22,142 [exception:handle_uncaught_exception] [ERROR]- Internal Server Error: /listGood/
Traceback (most recent call last):
  File "C:\Python27\lib\site-packages\django\core\handlers\exception.py", line 41, in inner
    response = get_response(request)
  File "C:\Python27\lib\site-packages\django\core\handlers\base.py", line 187, in _get_response
    response = self.process_exception_by_middleware(e, request)
  File "C:\Python27\lib\site-packages\django\core\handlers\base.py", line 185, in _get_response
    response = wrapped_callback(request, *callback_args, **callback_kwargs)
  File "E:\wx\wxH\vipMangementSystem\vms\JWT.py", line 77, in __deco
    return func(request, *para, **kw)
  File "E:\wx\wxH\vipMangementSystem\vms\views.py", line 248, in list_good
    good_type = data['label']
  File "C:\Python27\lib\site-packages\django\utils\datastructures.py", line 85, in __getitem__
    raise MultiValueDictKeyError(repr(key))
MultiValueDictKeyError: "u'label'"
2019-05-26 15:10:09,604 [exception:handle_uncaught_exception] [ERROR]- Internal Server Error: /listGood/
Traceback (most recent call last):
  File "C:\Python27\lib\site-packages\django\core\handlers\exception.py", line 41, in inner
    response = get_response(request)
  File "C:\Python27\lib\site-packages\django\core\handlers\base.py", line 187, in _get_response
    response = self.process_exception_by_middleware(e, request)
  File "C:\Python27\lib\site-packages\django\core\handlers\base.py", line 185, in _get_response
    response = wrapped_callback(request, *callback_args, **callback_kwargs)
  File "E:\wx\wxH\vipMangementSystem\vms\JWT.py", line 77, in __deco
    return func(request, *para, **kw)
  File "E:\wx\wxH\vipMangementSystem\vms\views.py", line 248, in list_good
    good_type = data['label']
  File "C:\Python27\lib\site-packages\django\utils\datastructures.py", line 85, in __getitem__
    raise MultiValueDictKeyError(repr(key))
MultiValueDictKeyError: "u'label'"
2019-05-26 15:33:42,681 [exception:handle_uncaught_exception] [ERROR]- Internal Server Error: /addGood/
Traceback (most recent call last):
  File "C:\Python27\lib\site-packages\django\core\handlers\exception.py", line 41, in inner
    response = get_response(request)
  File "C:\Python27\lib\site-packages\django\core\handlers\base.py", line 187, in _get_response
    response = self.process_exception_by_middleware(e, request)
  File "C:\Python27\lib\site-packages\django\core\handlers\base.py", line 185, in _get_response
    response = wrapped_callback(request, *callback_args, **callback_kwargs)
  File "E:\wx\wxH\vipMangementSystem\vms\JWT.py", line 77, in __deco
    return func(request, *para, **kw)
  File "E:\wx\wxH\vipMangementSystem\vms\views.py", line 330, in add_good
    count = str(int(data['add_count'])+int(data['count']))
  File "C:\Python27\lib\site-packages\django\utils\datastructures.py", line 85, in __getitem__
    raise MultiValueDictKeyError(repr(key))
MultiValueDictKeyError: "u'add_count'"
2019-05-26 15:36:30,058 [exception:handle_uncaught_exception] [ERROR]- Internal Server Error: /addGood/
Traceback (most recent call last):
  File "C:\Python27\lib\site-packages\django\core\handlers\exception.py", line 41, in inner
    response = get_response(request)
  File "C:\Python27\lib\site-packages\django\core\handlers\base.py", line 187, in _get_response
    response = self.process_exception_by_middleware(e, request)
  File "C:\Python27\lib\site-packages\django\core\handlers\base.py", line 185, in _get_response
    response = wrapped_callback(request, *callback_args, **callback_kwargs)
  File "E:\wx\wxH\vipMangementSystem\vms\JWT.py", line 77, in __deco
    return func(request, *para, **kw)
  File "E:\wx\wxH\vipMangementSystem\vms\views.py", line 330, in add_good
    count = str(int(data['add_count'])+int(data['count']))
  File "C:\Python27\lib\site-packages\django\utils\datastructures.py", line 85, in __getitem__
    raise MultiValueDictKeyError(repr(key))
MultiValueDictKeyError: "u'add_count'"
2019-05-26 15:37:48,279 [exception:handle_uncaught_exception] [ERROR]- Internal Server Error: /addGood/
Traceback (most recent call last):
  File "C:\Python27\lib\site-packages\django\core\handlers\exception.py", line 41, in inner
    response = get_response(request)
  File "C:\Python27\lib\site-packages\django\core\handlers\base.py", line 187, in _get_response
    response = self.process_exception_by_middleware(e, request)
  File "C:\Python27\lib\site-packages\django\core\handlers\base.py", line 185, in _get_response
    response = wrapped_callback(request, *callback_args, **callback_kwargs)
  File "E:\wx\wxH\vipMangementSystem\vms\JWT.py", line 77, in __deco
    return func(request, *para, **kw)
  File "E:\wx\wxH\vipMangementSystem\vms\views.py", line 330, in add_good
    count = str(int(data['add_count'])+int(data['count']))
  File "C:\Python27\lib\site-packages\django\utils\datastructures.py", line 85, in __getitem__
    raise MultiValueDictKeyError(repr(key))
MultiValueDictKeyError: "u'add_count'"
2019-05-26 15:39:47,073 [exception:handle_uncaught_exception] [ERROR]- Internal Server Error: /addGood/
Traceback (most recent call last):
  File "C:\Python27\lib\site-packages\django\core\handlers\exception.py", line 41, in inner
    response = get_response(request)
  File "C:\Python27\lib\site-packages\django\core\handlers\base.py", line 187, in _get_response
    response = self.process_exception_by_middleware(e, request)
  File "C:\Python27\lib\site-packages\django\core\handlers\base.py", line 185, in _get_response
    response = wrapped_callback(request, *callback_args, **callback_kwargs)
  File "E:\wx\wxH\vipMangementSystem\vms\JWT.py", line 77, in __deco
    return func(request, *para, **kw)
  File "E:\wx\wxH\vipMangementSystem\vms\views.py", line 330, in add_good
    count = str(int(data['add_count'])+int(data['count']))
  File "C:\Python27\lib\site-packages\django\utils\datastructures.py", line 85, in __getitem__
    raise MultiValueDictKeyError(repr(key))
MultiValueDictKeyError: "u'add_count'"
2019-05-26 15:43:19,213 [exception:handle_uncaught_exception] [ERROR]- Internal Server Error: /addGood/
Traceback (most recent call last):
  File "C:\Python27\lib\site-packages\django\core\handlers\exception.py", line 41, in inner
    response = get_response(request)
  File "C:\Python27\lib\site-packages\django\core\handlers\base.py", line 187, in _get_response
    response = self.process_exception_by_middleware(e, request)
  File "C:\Python27\lib\site-packages\django\core\handlers\base.py", line 185, in _get_response
    response = wrapped_callback(request, *callback_args, **callback_kwargs)
  File "E:\wx\wxH\vipMangementSystem\vms\JWT.py", line 77, in __deco
    return func(request, *para, **kw)
  File "E:\wx\wxH\vipMangementSystem\vms\views.py", line 331, in add_good
    count = str(int(data['add_count'])+int(data['count']))
  File "C:\Python27\lib\site-packages\django\utils\datastructures.py", line 85, in __getitem__
    raise MultiValueDictKeyError(repr(key))
MultiValueDictKeyError: "u'add_count'"
2019-05-26 15:43:55,160 [exception:handle_uncaught_exception] [ERROR]- Internal Server Error: /addGood/
Traceback (most recent call last):
  File "C:\Python27\lib\site-packages\django\core\handlers\exception.py", line 41, in inner
    response = get_response(request)
  File "C:\Python27\lib\site-packages\django\core\handlers\base.py", line 187, in _get_response
    response = self.process_exception_by_middleware(e, request)
  File "C:\Python27\lib\site-packages\django\core\handlers\base.py", line 185, in _get_response
    response = wrapped_callback(request, *callback_args, **callback_kwargs)
  File "E:\wx\wxH\vipMangementSystem\vms\JWT.py", line 77, in __deco
    return func(request, *para, **kw)
  File "E:\wx\wxH\vipMangementSystem\vms\views.py", line 330, in add_good
    count = str(int(data['add_count'])+int(data['count']))
  File "C:\Python27\lib\site-packages\django\utils\datastructures.py", line 85, in __getitem__
    raise MultiValueDictKeyError(repr(key))
MultiValueDictKeyError: "u'add_count'"
