2018-08-22 09:44:32,253 [exception:handle_uncaught_exception] [ERROR]- Internal Server Error: /listOrder/
Traceback (most recent call last):
  File "C:\Python27\lib\site-packages\django\core\handlers\exception.py", line 41, in inner
    response = get_response(request)
  File "C:\Python27\lib\site-packages\django\core\handlers\base.py", line 187, in _get_response
    response = self.process_exception_by_middleware(e, request)
  File "C:\Python27\lib\site-packages\django\core\handlers\base.py", line 185, in _get_response
    response = wrapped_callback(request, *callback_args, **callback_kwargs)
  File "D:\Study\VMS\vipMangementSystem\vms\views.py", line 602, in list_order
    elif x['state'] == 1 or x['state' ==2]:
KeyError: False
2018-08-22 10:15:26,838 [exception:handle_uncaught_exception] [ERROR]- Internal Server Error: /editServer/
Traceback (most recent call last):
  File "C:\Python27\lib\site-packages\django\core\handlers\exception.py", line 41, in inner
    response = get_response(request)
  File "C:\Python27\lib\site-packages\django\core\handlers\base.py", line 187, in _get_response
    response = self.process_exception_by_middleware(e, request)
  File "C:\Python27\lib\site-packages\django\core\handlers\base.py", line 185, in _get_response
    response = wrapped_callback(request, *callback_args, **callback_kwargs)
  File "D:\Study\VMS\vipMangementSystem\vms\views.py", line 517, in edit_server
    sql2 = "SELECT * from server where `name` ='%s' and id != '%s'" % (data['name'], data['id'])
  File "C:\Python27\lib\site-packages\django\utils\datastructures.py", line 85, in __getitem__
    raise MultiValueDictKeyError(repr(key))
MultiValueDictKeyError: "u'name'"
2018-08-22 10:16:37,986 [exception:handle_uncaught_exception] [ERROR]- Internal Server Error: /editServer/
Traceback (most recent call last):
  File "C:\Python27\lib\site-packages\django\core\handlers\exception.py", line 41, in inner
    response = get_response(request)
  File "C:\Python27\lib\site-packages\django\core\handlers\base.py", line 187, in _get_response
    response = self.process_exception_by_middleware(e, request)
  File "C:\Python27\lib\site-packages\django\core\handlers\base.py", line 185, in _get_response
    response = wrapped_callback(request, *callback_args, **callback_kwargs)
  File "D:\Study\VMS\vipMangementSystem\vms\views.py", line 517, in edit_server
    sql2 = "SELECT * from server where `name` ='%s' and id != '%s'" % (data['name'], data['id'])
  File "C:\Python27\lib\site-packages\django\utils\datastructures.py", line 85, in __getitem__
    raise MultiValueDictKeyError(repr(key))
MultiValueDictKeyError: "u'id'"
2018-08-22 10:18:15,802 [exception:handle_uncaught_exception] [ERROR]- Internal Server Error: /editServer/
Traceback (most recent call last):
  File "C:\Python27\lib\site-packages\django\core\handlers\exception.py", line 41, in inner
    response = get_response(request)
  File "C:\Python27\lib\site-packages\django\core\handlers\base.py", line 187, in _get_response
    response = self.process_exception_by_middleware(e, request)
  File "C:\Python27\lib\site-packages\django\core\handlers\base.py", line 185, in _get_response
    response = wrapped_callback(request, *callback_args, **callback_kwargs)
  File "D:\Study\VMS\vipMangementSystem\vms\views.py", line 517, in edit_server
    sql2 = "SELECT * from server where `name` ='%s' and id != '%s'" % (data['name'], data['id'])
  File "C:\Python27\lib\site-packages\django\utils\datastructures.py", line 85, in __getitem__
    raise MultiValueDictKeyError(repr(key))
MultiValueDictKeyError: "u'id'"
2018-08-22 10:22:57,640 [exception:handle_uncaught_exception] [ERROR]- Internal Server Error: /editServer/
Traceback (most recent call last):
  File "C:\Python27\lib\site-packages\django\core\handlers\exception.py", line 41, in inner
    response = get_response(request)
  File "C:\Python27\lib\site-packages\django\core\handlers\base.py", line 187, in _get_response
    response = self.process_exception_by_middleware(e, request)
  File "C:\Python27\lib\site-packages\django\core\handlers\base.py", line 185, in _get_response
    response = wrapped_callback(request, *callback_args, **callback_kwargs)
  File "D:\Study\VMS\vipMangementSystem\vms\views.py", line 517, in edit_server
    sql2 = "SELECT * from server where `name` ='%s' and id != '%s'" % (data['name'], data['id'])
  File "C:\Python27\lib\site-packages\django\utils\datastructures.py", line 85, in __getitem__
    raise MultiValueDictKeyError(repr(key))
MultiValueDictKeyError: "u'id'"
2018-08-22 10:23:24,450 [exception:handle_uncaught_exception] [ERROR]- Internal Server Error: /editServer/
Traceback (most recent call last):
  File "C:\Python27\lib\site-packages\django\core\handlers\exception.py", line 41, in inner
    response = get_response(request)
  File "C:\Python27\lib\site-packages\django\core\handlers\base.py", line 187, in _get_response
    response = self.process_exception_by_middleware(e, request)
  File "C:\Python27\lib\site-packages\django\core\handlers\base.py", line 185, in _get_response
    response = wrapped_callback(request, *callback_args, **callback_kwargs)
  File "D:\Study\VMS\vipMangementSystem\vms\views.py", line 531, in edit_server
    sql = "UPDATE server SET  `name` = '%s',server_category_id= '%s',price='%s' WHERE id='%s'" % (data['title'], data['type'], data['price'],data['id'])
  File "C:\Python27\lib\site-packages\django\utils\datastructures.py", line 85, in __getitem__
    raise MultiValueDictKeyError(repr(key))
MultiValueDictKeyError: "u'title'"
2018-08-22 10:39:29,148 [exception:handle_uncaught_exception] [ERROR]- Internal Server Error: /editServer/
Traceback (most recent call last):
  File "C:\Python27\lib\site-packages\django\core\handlers\exception.py", line 41, in inner
    response = get_response(request)
  File "C:\Python27\lib\site-packages\django\core\handlers\base.py", line 187, in _get_response
    response = self.process_exception_by_middleware(e, request)
  File "C:\Python27\lib\site-packages\django\core\handlers\base.py", line 185, in _get_response
    response = wrapped_callback(request, *callback_args, **callback_kwargs)
  File "D:\Study\VMS\vipMangementSystem\vms\views.py", line 531, in edit_server
    result = db.getOne("SELECT * from server where id == '%s'" % ( data['id']))
  File "D:\Study\VMS\vipMangementSystem\vms\DB.py", line 264, in getOne
    count = self._cursor.execute(sql)
  File "C:\Python27\lib\site-packages\DBUtils\SteadyDB.py", line 580, in tough_method
    result = method(*args, **kwargs)  # try to execute
  File "C:\Python27\lib\site-packages\MySQLdb\cursors.py", line 174, in execute
    self.errorhandler(self, exc, value)
  File "C:\Python27\lib\site-packages\MySQLdb\connections.py", line 36, in defaulterrorhandler
    raise errorclass, errorvalue
ProgrammingError: (1064, "You have an error in your SQL syntax; check the manual that corresponds to your MySQL server version for the right syntax to use near '== '1'' at line 1")
2018-08-22 10:39:41,605 [exception:handle_uncaught_exception] [ERROR]- Internal Server Error: /editServer/
Traceback (most recent call last):
  File "C:\Python27\lib\site-packages\django\core\handlers\exception.py", line 41, in inner
    response = get_response(request)
  File "C:\Python27\lib\site-packages\django\core\handlers\base.py", line 187, in _get_response
    response = self.process_exception_by_middleware(e, request)
  File "C:\Python27\lib\site-packages\django\core\handlers\base.py", line 185, in _get_response
    response = wrapped_callback(request, *callback_args, **callback_kwargs)
  File "D:\Study\VMS\vipMangementSystem\vms\views.py", line 531, in edit_server
    result = db.getOne("SELECT * from server where id == '%s'" % ( data['id']))
  File "D:\Study\VMS\vipMangementSystem\vms\DB.py", line 264, in getOne
    count = self._cursor.execute(sql)
  File "C:\Python27\lib\site-packages\DBUtils\SteadyDB.py", line 580, in tough_method
    result = method(*args, **kwargs)  # try to execute
  File "C:\Python27\lib\site-packages\MySQLdb\cursors.py", line 174, in execute
    self.errorhandler(self, exc, value)
  File "C:\Python27\lib\site-packages\MySQLdb\connections.py", line 36, in defaulterrorhandler
    raise errorclass, errorvalue
ProgrammingError: (1064, "You have an error in your SQL syntax; check the manual that corresponds to your MySQL server version for the right syntax to use near '== '1'' at line 1")
2018-08-22 11:55:38,953 [base:get_response] [WARNING]- Not Found: /favicon.ico
2018-08-30 22:37:46,418 [exception:handle_uncaught_exception] [ERROR]- Internal Server Error: /listVipPerson/
Traceback (most recent call last):
  File "C:\Python27\lib\site-packages\django\core\handlers\exception.py", line 41, in inner
    response = get_response(request)
  File "C:\Python27\lib\site-packages\django\core\handlers\base.py", line 187, in _get_response
    response = self.process_exception_by_middleware(e, request)
  File "C:\Python27\lib\site-packages\django\core\handlers\base.py", line 185, in _get_response
    response = wrapped_callback(request, *callback_args, **callback_kwargs)
  File "D:\Study\VMS\vipMangementSystem\vms\views.py", line 46, in list_vip_person
    query_result = db.getAll(sql)
  File "D:\Study\VMS\vipMangementSystem\vms\DB.py", line 247, in getAll
    count = self._cursor.execute(sql)
  File "C:\Python27\lib\site-packages\DBUtils\SteadyDB.py", line 661, in tough_method
    raise error  # reraise the original error again
OperationalError: (1582, "Incorrect parameter count in the call to native function 'isnull'")
2018-08-31 00:01:11,118 [exception:handle_uncaught_exception] [ERROR]- Internal Server Error: /endOrder/
Traceback (most recent call last):
  File "C:\Python27\lib\site-packages\django\core\handlers\exception.py", line 41, in inner
    response = get_response(request)
  File "C:\Python27\lib\site-packages\django\core\handlers\base.py", line 187, in _get_response
    response = self.process_exception_by_middleware(e, request)
  File "C:\Python27\lib\site-packages\django\core\handlers\base.py", line 185, in _get_response
    response = wrapped_callback(request, *callback_args, **callback_kwargs)
  File "D:\Study\VMS\vipMangementSystem\vms\views.py", line 872, in end_order
    sql2 = "INSERT INTO `vms`.`point_detail`( `person_id`, `order_id`, `type`, `point`, `create_time`) VALUES ('%s', '%s', 1,'%s', now());"%(result['person_id'],result['id'],str(0-float(point)))
TypeError: float() argument must be a string or a number
2018-08-31 00:02:25,996 [exception:handle_uncaught_exception] [ERROR]- Internal Server Error: /endOrder/
Traceback (most recent call last):
  File "C:\Python27\lib\site-packages\django\core\handlers\exception.py", line 41, in inner
    response = get_response(request)
  File "C:\Python27\lib\site-packages\django\core\handlers\base.py", line 187, in _get_response
    response = self.process_exception_by_middleware(e, request)
  File "C:\Python27\lib\site-packages\django\core\handlers\base.py", line 185, in _get_response
    response = wrapped_callback(request, *callback_args, **callback_kwargs)
  File "D:\Study\VMS\vipMangementSystem\vms\views.py", line 873, in end_order
    sql2 = "INSERT INTO `vms`.`point_detail`( `person_id`, `order_id`, `type`, `point`, `create_time`) VALUES ('%s', '%s', 1,'%s', now());"%(result['person_id'],result['id'],str(0-float(point)))
TypeError: float() argument must be a string or a number
2018-08-31 00:14:50,502 [exception:handle_uncaught_exception] [ERROR]- Internal Server Error: /endOrder/
Traceback (most recent call last):
  File "C:\Python27\lib\site-packages\django\core\handlers\exception.py", line 41, in inner
    response = get_response(request)
  File "C:\Python27\lib\site-packages\django\core\handlers\base.py", line 187, in _get_response
    response = self.process_exception_by_middleware(e, request)
  File "C:\Python27\lib\site-packages\django\core\handlers\base.py", line 185, in _get_response
    response = wrapped_callback(request, *callback_args, **callback_kwargs)
  File "D:\Study\VMS\vipMangementSystem\vms\views.py", line 876, in end_order
    all_money-float(point), data['lay_value'], data['free_value'], data['orderid'])
TypeError: float() argument must be a string or a number
2018-08-31 00:16:15,135 [exception:handle_uncaught_exception] [ERROR]- Internal Server Error: /endOrder/
Traceback (most recent call last):
  File "C:\Python27\lib\site-packages\django\core\handlers\exception.py", line 41, in inner
    response = get_response(request)
  File "C:\Python27\lib\site-packages\django\core\handlers\base.py", line 187, in _get_response
    response = self.process_exception_by_middleware(e, request)
  File "C:\Python27\lib\site-packages\django\core\handlers\base.py", line 185, in _get_response
    response = wrapped_callback(request, *callback_args, **callback_kwargs)
  File "D:\Study\VMS\vipMangementSystem\vms\views.py", line 876, in end_order
    (all_money-float(point)), data['lay_value'], data['free_value'], data['orderid'])
TypeError: float() argument must be a string or a number
2018-08-31 00:19:15,496 [exception:handle_uncaught_exception] [ERROR]- Internal Server Error: /endOrder/
Traceback (most recent call last):
  File "C:\Python27\lib\site-packages\django\core\handlers\exception.py", line 41, in inner
    response = get_response(request)
  File "C:\Python27\lib\site-packages\django\core\handlers\base.py", line 187, in _get_response
    response = self.process_exception_by_middleware(e, request)
  File "C:\Python27\lib\site-packages\django\core\handlers\base.py", line 185, in _get_response
    response = wrapped_callback(request, *callback_args, **callback_kwargs)
  File "D:\Study\VMS\vipMangementSystem\vms\views.py", line 873, in end_order
    sql2 = "INSERT INTO `vms`.`point_detail`( `person_id`, `order_id`, `type`, `point`, `create_time`) VALUES ('%s', '%s', 1,'%s', now());"%(result['person_id'],result['id'],str(0-float(point)))
TypeError: float() argument must be a string or a number
2018-08-31 00:21:44,667 [exception:handle_uncaught_exception] [ERROR]- Internal Server Error: /endOrder/
Traceback (most recent call last):
  File "C:\Python27\lib\site-packages\django\core\handlers\exception.py", line 41, in inner
    response = get_response(request)
  File "C:\Python27\lib\site-packages\django\core\handlers\base.py", line 187, in _get_response
    response = self.process_exception_by_middleware(e, request)
  File "C:\Python27\lib\site-packages\django\core\handlers\base.py", line 185, in _get_response
    response = wrapped_callback(request, *callback_args, **callback_kwargs)
  File "D:\Study\VMS\vipMangementSystem\vms\views.py", line 873, in end_order
    sql2 = "INSERT INTO `vms`.`point_detail`( `person_id`, `order_id`, `type`, `point`, `create_time`) VALUES ('%s', '%s', 1,'%s', now());"%(result['person_id'],result['id'],str(0-float(point)))
TypeError: float() argument must be a string or a number
2018-08-31 00:51:59,441 [exception:handle_uncaught_exception] [ERROR]- Internal Server Error: /endOrder/
Traceback (most recent call last):
  File "C:\Python27\lib\site-packages\django\core\handlers\exception.py", line 41, in inner
    response = get_response(request)
  File "C:\Python27\lib\site-packages\django\core\handlers\base.py", line 187, in _get_response
    response = self.process_exception_by_middleware(e, request)
  File "C:\Python27\lib\site-packages\django\core\handlers\base.py", line 185, in _get_response
    response = wrapped_callback(request, *callback_args, **callback_kwargs)
  File "D:\Study\VMS\vipMangementSystem\vms\views.py", line 873, in end_order
    sql2 = "INSERT INTO `vms`.`point_detail`( `person_id`, `order_id`, `type`, `point`, `create_time`) VALUES ('%s', '%s', 1,'%s', now());"%(result['person_id'],result['id'],str(0-float(point['valid_point'])))
TypeError: float() argument must be a string or a number
2018-08-31 00:53:36,305 [exception:handle_uncaught_exception] [ERROR]- Internal Server Error: /endOrder/
Traceback (most recent call last):
  File "C:\Python27\lib\site-packages\django\core\handlers\exception.py", line 41, in inner
    response = get_response(request)
  File "C:\Python27\lib\site-packages\django\core\handlers\base.py", line 187, in _get_response
    response = self.process_exception_by_middleware(e, request)
  File "C:\Python27\lib\site-packages\django\core\handlers\base.py", line 185, in _get_response
    response = wrapped_callback(request, *callback_args, **callback_kwargs)
  File "D:\Study\VMS\vipMangementSystem\vms\views.py", line 877, in end_order
    offset_point = float(point['valid_point']) / 10
TypeError: 'int' object has no attribute '__getitem__'
2018-09-01 15:07:12,414 [exception:handle_uncaught_exception] [ERROR]- Internal Server Error: /managerLogin/
Traceback (most recent call last):
  File "C:\Python27\lib\site-packages\django\core\handlers\exception.py", line 41, in inner
    response = get_response(request)
  File "C:\Python27\lib\site-packages\django\core\handlers\base.py", line 187, in _get_response
    response = self.process_exception_by_middleware(e, request)
  File "C:\Python27\lib\site-packages\django\core\handlers\base.py", line 185, in _get_response
    response = wrapped_callback(request, *callback_args, **callback_kwargs)
  File "D:\Study\VMS\vipMangementSystem\vms\views.py", line 959, in manager_login
    access_token = JWT.create_token(username)
TypeError: unbound method create_token() must be called with JWT instance as first argument (got unicode instance instead)
2018-09-01 15:09:13,523 [exception:handle_uncaught_exception] [ERROR]- Internal Server Error: /managerLogin/
Traceback (most recent call last):
  File "C:\Python27\lib\site-packages\django\core\handlers\exception.py", line 41, in inner
    response = get_response(request)
  File "C:\Python27\lib\site-packages\django\core\handlers\base.py", line 187, in _get_response
    response = self.process_exception_by_middleware(e, request)
  File "C:\Python27\lib\site-packages\django\core\handlers\base.py", line 185, in _get_response
    response = wrapped_callback(request, *callback_args, **callback_kwargs)
  File "D:/Study/VMS/vipMangementSystem\vms\views.py", line 959, in manager_login
    access_token = JWT.create_token(username)
TypeError: unbound method create_token() must be called with JWT instance as first argument (got unicode instance instead)
2018-09-01 15:09:30,490 [exception:handle_uncaught_exception] [ERROR]- Internal Server Error: /managerLogin/
Traceback (most recent call last):
  File "C:\Python27\lib\site-packages\django\core\handlers\exception.py", line 41, in inner
    response = get_response(request)
  File "C:\Python27\lib\site-packages\django\core\handlers\base.py", line 187, in _get_response
    response = self.process_exception_by_middleware(e, request)
  File "C:\Python27\lib\site-packages\django\core\handlers\base.py", line 185, in _get_response
    response = wrapped_callback(request, *callback_args, **callback_kwargs)
  File "D:/Study/VMS/vipMangementSystem\vms\views.py", line 959, in manager_login
    access_token = JWT.create_token(username)
TypeError: unbound method create_token() must be called with JWT instance as first argument (got unicode instance instead)
2018-09-01 15:18:59,345 [exception:handle_uncaught_exception] [ERROR]- Internal Server Error: /listVipPerson/
Traceback (most recent call last):
  File "C:\Python27\lib\site-packages\django\core\handlers\exception.py", line 41, in inner
    response = get_response(request)
  File "C:\Python27\lib\site-packages\django\core\handlers\base.py", line 187, in _get_response
    response = self.process_exception_by_middleware(e, request)
  File "C:\Python27\lib\site-packages\django\core\handlers\base.py", line 185, in _get_response
    response = wrapped_callback(request, *callback_args, **callback_kwargs)
  File "D:/Study/VMS/vipMangementSystem\vms\views.py", line 27, in list_vip_person
    if jwt.verify_bearer_token(req.GET.get('access_token')):
  File "D:/Study/VMS/vipMangementSystem\vms\JWT.py", line 33, in verify_bearer_token
    payload = jwt.decode(token, 'ssss',  algorithms=['HS256'])
  File "C:\Python27\lib\site-packages\jwt\api_jwt.py", line 93, in decode
    jwt, key=key, algorithms=algorithms, options=options, **kwargs
  File "C:\Python27\lib\site-packages\jwt\api_jws.py", line 157, in decode
    key, algorithms)
  File "C:\Python27\lib\site-packages\jwt\api_jws.py", line 224, in _verify_signature
    raise InvalidSignatureError('Signature verification failed')
InvalidSignatureError: Signature verification failed
2018-09-01 15:19:22,707 [exception:handle_uncaught_exception] [ERROR]- Internal Server Error: /listVipPerson/
Traceback (most recent call last):
  File "C:\Python27\lib\site-packages\django\core\handlers\exception.py", line 41, in inner
    response = get_response(request)
  File "C:\Python27\lib\site-packages\django\core\handlers\base.py", line 187, in _get_response
    response = self.process_exception_by_middleware(e, request)
  File "C:\Python27\lib\site-packages\django\core\handlers\base.py", line 185, in _get_response
    response = wrapped_callback(request, *callback_args, **callback_kwargs)
  File "D:/Study/VMS/vipMangementSystem\vms\views.py", line 27, in list_vip_person
    if jwt.verify_bearer_token(req.GET.get('access_token')):
  File "D:/Study/VMS/vipMangementSystem\vms\JWT.py", line 33, in verify_bearer_token
    payload = jwt.decode(token, '1',  algorithms=['HS256'])
  File "C:\Python27\lib\site-packages\jwt\api_jwt.py", line 93, in decode
    jwt, key=key, algorithms=algorithms, options=options, **kwargs
  File "C:\Python27\lib\site-packages\jwt\api_jws.py", line 157, in decode
    key, algorithms)
  File "C:\Python27\lib\site-packages\jwt\api_jws.py", line 224, in _verify_signature
    raise InvalidSignatureError('Signature verification failed')
InvalidSignatureError: Signature verification failed
2018-09-01 15:19:29,348 [exception:handle_uncaught_exception] [ERROR]- Internal Server Error: /listVipPerson/
Traceback (most recent call last):
  File "C:\Python27\lib\site-packages\django\core\handlers\exception.py", line 41, in inner
    response = get_response(request)
  File "C:\Python27\lib\site-packages\django\core\handlers\base.py", line 187, in _get_response
    response = self.process_exception_by_middleware(e, request)
  File "C:\Python27\lib\site-packages\django\core\handlers\base.py", line 185, in _get_response
    response = wrapped_callback(request, *callback_args, **callback_kwargs)
  File "D:/Study/VMS/vipMangementSystem\vms\views.py", line 27, in list_vip_person
    if jwt.verify_bearer_token(req.GET.get('access_token')):
  File "D:/Study/VMS/vipMangementSystem\vms\JWT.py", line 33, in verify_bearer_token
    payload = jwt.decode(token, '1',  algorithms=['HS256'])
  File "C:\Python27\lib\site-packages\jwt\api_jwt.py", line 93, in decode
    jwt, key=key, algorithms=algorithms, options=options, **kwargs
  File "C:\Python27\lib\site-packages\jwt\api_jws.py", line 157, in decode
    key, algorithms)
  File "C:\Python27\lib\site-packages\jwt\api_jws.py", line 224, in _verify_signature
    raise InvalidSignatureError('Signature verification failed')
InvalidSignatureError: Signature verification failed
2018-09-01 15:22:19,950 [exception:handle_uncaught_exception] [ERROR]- Internal Server Error: /listVipPerson/
Traceback (most recent call last):
  File "C:\Python27\lib\site-packages\django\core\handlers\exception.py", line 41, in inner
    response = get_response(request)
  File "C:\Python27\lib\site-packages\django\core\handlers\base.py", line 187, in _get_response
    response = self.process_exception_by_middleware(e, request)
  File "C:\Python27\lib\site-packages\django\core\handlers\base.py", line 185, in _get_response
    response = wrapped_callback(request, *callback_args, **callback_kwargs)
  File "D:/Study/VMS/vipMangementSystem\vms\views.py", line 27, in list_vip_person
    if jwt.verify_bearer_token(req.GET.get('access_token')):
  File "D:/Study/VMS/vipMangementSystem\vms\JWT.py", line 33, in verify_bearer_token
    payload = jwt.decode(token, 'mothanty',  algorithms=['HS256'])
  File "C:\Python27\lib\site-packages\jwt\api_jwt.py", line 93, in decode
    jwt, key=key, algorithms=algorithms, options=options, **kwargs
  File "C:\Python27\lib\site-packages\jwt\api_jws.py", line 157, in decode
    key, algorithms)
  File "C:\Python27\lib\site-packages\jwt\api_jws.py", line 224, in _verify_signature
    raise InvalidSignatureError('Signature verification failed')
InvalidSignatureError: Signature verification failed
2018-09-01 15:24:12,938 [exception:handle_uncaught_exception] [ERROR]- Internal Server Error: /listVipPerson/
Traceback (most recent call last):
  File "C:\Python27\lib\site-packages\django\core\handlers\exception.py", line 41, in inner
    response = get_response(request)
  File "C:\Python27\lib\site-packages\django\core\handlers\base.py", line 187, in _get_response
    response = self.process_exception_by_middleware(e, request)
  File "C:\Python27\lib\site-packages\django\core\handlers\base.py", line 185, in _get_response
    response = wrapped_callback(request, *callback_args, **callback_kwargs)
  File "D:/Study/VMS/vipMangementSystem\vms\views.py", line 27, in list_vip_person
    if jwt.verify_bearer_token(req.GET.get('access_token')):
  File "D:/Study/VMS/vipMangementSystem\vms\JWT.py", line 33, in verify_bearer_token
    payload = jwt.decode(token, '1',  algorithms=['HS256'])
  File "C:\Python27\lib\site-packages\jwt\api_jwt.py", line 93, in decode
    jwt, key=key, algorithms=algorithms, options=options, **kwargs
  File "C:\Python27\lib\site-packages\jwt\api_jws.py", line 157, in decode
    key, algorithms)
  File "C:\Python27\lib\site-packages\jwt\api_jws.py", line 224, in _verify_signature
    raise InvalidSignatureError('Signature verification failed')
InvalidSignatureError: Signature verification failed
2018-09-01 15:24:20,683 [exception:handle_uncaught_exception] [ERROR]- Internal Server Error: /listVipPerson/
Traceback (most recent call last):
  File "C:\Python27\lib\site-packages\django\core\handlers\exception.py", line 41, in inner
    response = get_response(request)
  File "C:\Python27\lib\site-packages\django\core\handlers\base.py", line 187, in _get_response
    response = self.process_exception_by_middleware(e, request)
  File "C:\Python27\lib\site-packages\django\core\handlers\base.py", line 185, in _get_response
    response = wrapped_callback(request, *callback_args, **callback_kwargs)
  File "D:/Study/VMS/vipMangementSystem\vms\views.py", line 27, in list_vip_person
    if jwt.verify_bearer_token(req.GET.get('access_token')):
  File "D:/Study/VMS/vipMangementSystem\vms\JWT.py", line 33, in verify_bearer_token
    payload = jwt.decode(token, '1',  algorithms=['HS256'])
  File "C:\Python27\lib\site-packages\jwt\api_jwt.py", line 93, in decode
    jwt, key=key, algorithms=algorithms, options=options, **kwargs
  File "C:\Python27\lib\site-packages\jwt\api_jws.py", line 157, in decode
    key, algorithms)
  File "C:\Python27\lib\site-packages\jwt\api_jws.py", line 224, in _verify_signature
    raise InvalidSignatureError('Signature verification failed')
InvalidSignatureError: Signature verification failed
2018-09-01 15:24:21,989 [exception:handle_uncaught_exception] [ERROR]- Internal Server Error: /listVipPerson/
Traceback (most recent call last):
  File "C:\Python27\lib\site-packages\django\core\handlers\exception.py", line 41, in inner
    response = get_response(request)
  File "C:\Python27\lib\site-packages\django\core\handlers\base.py", line 187, in _get_response
    response = self.process_exception_by_middleware(e, request)
  File "C:\Python27\lib\site-packages\django\core\handlers\base.py", line 185, in _get_response
    response = wrapped_callback(request, *callback_args, **callback_kwargs)
  File "D:/Study/VMS/vipMangementSystem\vms\views.py", line 27, in list_vip_person
    if jwt.verify_bearer_token(req.GET.get('access_token')):
  File "D:/Study/VMS/vipMangementSystem\vms\JWT.py", line 33, in verify_bearer_token
    payload = jwt.decode(token, '1',  algorithms=['HS256'])
  File "C:\Python27\lib\site-packages\jwt\api_jwt.py", line 93, in decode
    jwt, key=key, algorithms=algorithms, options=options, **kwargs
  File "C:\Python27\lib\site-packages\jwt\api_jws.py", line 157, in decode
    key, algorithms)
  File "C:\Python27\lib\site-packages\jwt\api_jws.py", line 224, in _verify_signature
    raise InvalidSignatureError('Signature verification failed')
InvalidSignatureError: Signature verification failed
2018-09-01 15:33:19,329 [exception:handle_uncaught_exception] [ERROR]- Internal Server Error: /listVipPerson/
Traceback (most recent call last):
  File "C:\Python27\lib\site-packages\django\core\handlers\exception.py", line 41, in inner
    response = get_response(request)
  File "C:\Python27\lib\site-packages\django\core\handlers\base.py", line 187, in _get_response
    response = self.process_exception_by_middleware(e, request)
  File "C:\Python27\lib\site-packages\django\core\handlers\base.py", line 185, in _get_response
    response = wrapped_callback(request, *callback_args, **callback_kwargs)
  File "D:/Study/VMS/vipMangementSystem\vms\views.py", line 27, in list_vip_person
    if jwt.verify_bearer_token(req.GET.get('access_token')):
  File "D:/Study/VMS/vipMangementSystem\vms\JWT.py", line 33, in verify_bearer_token
    payload = jwt.decode(token, '1',  algorithms=['HS256'])
  File "C:\Python27\lib\site-packages\jwt\api_jwt.py", line 93, in decode
    jwt, key=key, algorithms=algorithms, options=options, **kwargs
  File "C:\Python27\lib\site-packages\jwt\api_jws.py", line 157, in decode
    key, algorithms)
  File "C:\Python27\lib\site-packages\jwt\api_jws.py", line 224, in _verify_signature
    raise InvalidSignatureError('Signature verification failed')
InvalidSignatureError: Signature verification failed
2018-09-01 15:33:26,607 [exception:handle_uncaught_exception] [ERROR]- Internal Server Error: /listVipPerson/
Traceback (most recent call last):
  File "C:\Python27\lib\site-packages\django\core\handlers\exception.py", line 41, in inner
    response = get_response(request)
  File "C:\Python27\lib\site-packages\django\core\handlers\base.py", line 187, in _get_response
    response = self.process_exception_by_middleware(e, request)
  File "C:\Python27\lib\site-packages\django\core\handlers\base.py", line 185, in _get_response
    response = wrapped_callback(request, *callback_args, **callback_kwargs)
  File "D:/Study/VMS/vipMangementSystem\vms\views.py", line 27, in list_vip_person
    if jwt.verify_bearer_token(req.GET.get('access_token')):
  File "D:/Study/VMS/vipMangementSystem\vms\JWT.py", line 33, in verify_bearer_token
    payload = jwt.decode(token, '1',  algorithms=['HS256'])
  File "C:\Python27\lib\site-packages\jwt\api_jwt.py", line 93, in decode
    jwt, key=key, algorithms=algorithms, options=options, **kwargs
  File "C:\Python27\lib\site-packages\jwt\api_jws.py", line 157, in decode
    key, algorithms)
  File "C:\Python27\lib\site-packages\jwt\api_jws.py", line 224, in _verify_signature
    raise InvalidSignatureError('Signature verification failed')
InvalidSignatureError: Signature verification failed
2018-09-01 15:34:26,595 [exception:handle_uncaught_exception] [ERROR]- Internal Server Error: /listVipPerson/
Traceback (most recent call last):
  File "C:\Python27\lib\site-packages\django\core\handlers\exception.py", line 41, in inner
    response = get_response(request)
  File "C:\Python27\lib\site-packages\django\core\handlers\base.py", line 187, in _get_response
    response = self.process_exception_by_middleware(e, request)
  File "C:\Python27\lib\site-packages\django\core\handlers\base.py", line 185, in _get_response
    response = wrapped_callback(request, *callback_args, **callback_kwargs)
  File "D:/Study/VMS/vipMangementSystem\vms\views.py", line 27, in list_vip_person
    if jwt.verify_bearer_token(req.GET.get('access_token')):
  File "D:/Study/VMS/vipMangementSystem\vms\JWT.py", line 33, in verify_bearer_token
    payload = jwt.decode(token, '1',  algorithms=['HS256'])
  File "C:\Python27\lib\site-packages\jwt\api_jwt.py", line 93, in decode
    jwt, key=key, algorithms=algorithms, options=options, **kwargs
  File "C:\Python27\lib\site-packages\jwt\api_jws.py", line 157, in decode
    key, algorithms)
  File "C:\Python27\lib\site-packages\jwt\api_jws.py", line 224, in _verify_signature
    raise InvalidSignatureError('Signature verification failed')
InvalidSignatureError: Signature verification failed
2018-09-01 15:34:51,250 [exception:handle_uncaught_exception] [ERROR]- Internal Server Error: /listVipPerson/
Traceback (most recent call last):
  File "C:\Python27\lib\site-packages\django\core\handlers\exception.py", line 41, in inner
    response = get_response(request)
  File "C:\Python27\lib\site-packages\django\core\handlers\base.py", line 187, in _get_response
    response = self.process_exception_by_middleware(e, request)
  File "C:\Python27\lib\site-packages\django\core\handlers\base.py", line 185, in _get_response
    response = wrapped_callback(request, *callback_args, **callback_kwargs)
  File "D:/Study/VMS/vipMangementSystem\vms\views.py", line 27, in list_vip_person
    if jwt.verify_bearer_token(req.GET.get('access_token')):
  File "D:/Study/VMS/vipMangementSystem\vms\JWT.py", line 33, in verify_bearer_token
    payload = jwt.decode(token, '1',  algorithms=['HS256'])
  File "C:\Python27\lib\site-packages\jwt\api_jwt.py", line 93, in decode
    jwt, key=key, algorithms=algorithms, options=options, **kwargs
  File "C:\Python27\lib\site-packages\jwt\api_jws.py", line 157, in decode
    key, algorithms)
  File "C:\Python27\lib\site-packages\jwt\api_jws.py", line 224, in _verify_signature
    raise InvalidSignatureError('Signature verification failed')
InvalidSignatureError: Signature verification failed
2018-09-01 15:36:50,954 [exception:handle_uncaught_exception] [ERROR]- Internal Server Error: /listVipPerson/
Traceback (most recent call last):
  File "C:\Python27\lib\site-packages\django\core\handlers\exception.py", line 41, in inner
    response = get_response(request)
  File "C:\Python27\lib\site-packages\django\core\handlers\base.py", line 187, in _get_response
    response = self.process_exception_by_middleware(e, request)
  File "C:\Python27\lib\site-packages\django\core\handlers\base.py", line 185, in _get_response
    response = wrapped_callback(request, *callback_args, **callback_kwargs)
  File "D:/Study/VMS/vipMangementSystem\vms\views.py", line 27, in list_vip_person
    if jwt.verify_bearer_token(req.GET.get('access_token')):
  File "D:/Study/VMS/vipMangementSystem\vms\JWT.py", line 33, in verify_bearer_token
    payload = jwt.decode(token, 'mothanty',  algorithms=['HS256'])
  File "C:\Python27\lib\site-packages\jwt\api_jwt.py", line 105, in decode
    self._validate_claims(payload, merged_options, **kwargs)
  File "C:\Python27\lib\site-packages\jwt\api_jwt.py", line 135, in _validate_claims
    self._validate_exp(payload, now, leeway)
  File "C:\Python27\lib\site-packages\jwt\api_jwt.py", line 176, in _validate_exp
    raise ExpiredSignatureError('Signature has expired')
ExpiredSignatureError: Signature has expired
2018-09-01 15:38:01,174 [exception:handle_uncaught_exception] [ERROR]- Internal Server Error: /listVipPerson/
Traceback (most recent call last):
  File "C:\Python27\lib\site-packages\django\core\handlers\exception.py", line 41, in inner
    response = get_response(request)
  File "C:\Python27\lib\site-packages\django\core\handlers\base.py", line 187, in _get_response
    response = self.process_exception_by_middleware(e, request)
  File "C:\Python27\lib\site-packages\django\core\handlers\base.py", line 185, in _get_response
    response = wrapped_callback(request, *callback_args, **callback_kwargs)
  File "D:/Study/VMS/vipMangementSystem\vms\views.py", line 27, in list_vip_person
    if jwt.verify_bearer_token(req.GET.get('access_token')):
  File "D:/Study/VMS/vipMangementSystem\vms\JWT.py", line 33, in verify_bearer_token
    payload = jwt.decode(token, 'mothanty',  algorithms=['HS256'])
  File "C:\Python27\lib\site-packages\jwt\api_jwt.py", line 105, in decode
    self._validate_claims(payload, merged_options, **kwargs)
  File "C:\Python27\lib\site-packages\jwt\api_jwt.py", line 135, in _validate_claims
    self._validate_exp(payload, now, leeway)
  File "C:\Python27\lib\site-packages\jwt\api_jwt.py", line 176, in _validate_exp
    raise ExpiredSignatureError('Signature has expired')
ExpiredSignatureError: Signature has expired
2018-09-01 15:38:01,852 [exception:handle_uncaught_exception] [ERROR]- Internal Server Error: /listVipPerson/
Traceback (most recent call last):
  File "C:\Python27\lib\site-packages\django\core\handlers\exception.py", line 41, in inner
    response = get_response(request)
  File "C:\Python27\lib\site-packages\django\core\handlers\base.py", line 187, in _get_response
    response = self.process_exception_by_middleware(e, request)
  File "C:\Python27\lib\site-packages\django\core\handlers\base.py", line 185, in _get_response
    response = wrapped_callback(request, *callback_args, **callback_kwargs)
  File "D:/Study/VMS/vipMangementSystem\vms\views.py", line 27, in list_vip_person
    if jwt.verify_bearer_token(req.GET.get('access_token')):
  File "D:/Study/VMS/vipMangementSystem\vms\JWT.py", line 33, in verify_bearer_token
    payload = jwt.decode(token, 'mothanty',  algorithms=['HS256'])
  File "C:\Python27\lib\site-packages\jwt\api_jwt.py", line 105, in decode
    self._validate_claims(payload, merged_options, **kwargs)
  File "C:\Python27\lib\site-packages\jwt\api_jwt.py", line 135, in _validate_claims
    self._validate_exp(payload, now, leeway)
  File "C:\Python27\lib\site-packages\jwt\api_jwt.py", line 176, in _validate_exp
    raise ExpiredSignatureError('Signature has expired')
ExpiredSignatureError: Signature has expired
2018-09-01 15:38:03,371 [exception:handle_uncaught_exception] [ERROR]- Internal Server Error: /listVipPerson/
Traceback (most recent call last):
  File "C:\Python27\lib\site-packages\django\core\handlers\exception.py", line 41, in inner
    response = get_response(request)
  File "C:\Python27\lib\site-packages\django\core\handlers\base.py", line 187, in _get_response
    response = self.process_exception_by_middleware(e, request)
  File "C:\Python27\lib\site-packages\django\core\handlers\base.py", line 185, in _get_response
    response = wrapped_callback(request, *callback_args, **callback_kwargs)
  File "D:/Study/VMS/vipMangementSystem\vms\views.py", line 27, in list_vip_person
    if jwt.verify_bearer_token(req.GET.get('access_token')):
  File "D:/Study/VMS/vipMangementSystem\vms\JWT.py", line 33, in verify_bearer_token
    payload = jwt.decode(token, 'mothanty',  algorithms=['HS256'])
  File "C:\Python27\lib\site-packages\jwt\api_jwt.py", line 105, in decode
    self._validate_claims(payload, merged_options, **kwargs)
  File "C:\Python27\lib\site-packages\jwt\api_jwt.py", line 135, in _validate_claims
    self._validate_exp(payload, now, leeway)
  File "C:\Python27\lib\site-packages\jwt\api_jwt.py", line 176, in _validate_exp
    raise ExpiredSignatureError('Signature has expired')
ExpiredSignatureError: Signature has expired
2018-09-01 15:38:13,816 [exception:handle_uncaught_exception] [ERROR]- Internal Server Error: /listVipPerson/
Traceback (most recent call last):
  File "C:\Python27\lib\site-packages\django\core\handlers\exception.py", line 41, in inner
    response = get_response(request)
  File "C:\Python27\lib\site-packages\django\core\handlers\base.py", line 187, in _get_response
    response = self.process_exception_by_middleware(e, request)
  File "C:\Python27\lib\site-packages\django\core\handlers\base.py", line 185, in _get_response
    response = wrapped_callback(request, *callback_args, **callback_kwargs)
  File "D:/Study/VMS/vipMangementSystem\vms\views.py", line 27, in list_vip_person
    if jwt.verify_bearer_token(req.GET.get('access_token')):
  File "D:/Study/VMS/vipMangementSystem\vms\JWT.py", line 33, in verify_bearer_token
    payload = jwt.decode(token, 'mothanty',  algorithms=['HS256'])
  File "C:\Python27\lib\site-packages\jwt\api_jwt.py", line 105, in decode
    self._validate_claims(payload, merged_options, **kwargs)
  File "C:\Python27\lib\site-packages\jwt\api_jwt.py", line 135, in _validate_claims
    self._validate_exp(payload, now, leeway)
  File "C:\Python27\lib\site-packages\jwt\api_jwt.py", line 176, in _validate_exp
    raise ExpiredSignatureError('Signature has expired')
ExpiredSignatureError: Signature has expired
2018-09-01 15:38:20,085 [exception:handle_uncaught_exception] [ERROR]- Internal Server Error: /listVipPerson/
Traceback (most recent call last):
  File "C:\Python27\lib\site-packages\django\core\handlers\exception.py", line 41, in inner
    response = get_response(request)
  File "C:\Python27\lib\site-packages\django\core\handlers\base.py", line 187, in _get_response
    response = self.process_exception_by_middleware(e, request)
  File "C:\Python27\lib\site-packages\django\core\handlers\base.py", line 185, in _get_response
    response = wrapped_callback(request, *callback_args, **callback_kwargs)
  File "D:/Study/VMS/vipMangementSystem\vms\views.py", line 27, in list_vip_person
    if jwt.verify_bearer_token(req.GET.get('access_token')):
  File "D:/Study/VMS/vipMangementSystem\vms\JWT.py", line 33, in verify_bearer_token
    payload = jwt.decode(token, 'mothanty',  algorithms=['HS256'])
  File "C:\Python27\lib\site-packages\jwt\api_jwt.py", line 105, in decode
    self._validate_claims(payload, merged_options, **kwargs)
  File "C:\Python27\lib\site-packages\jwt\api_jwt.py", line 135, in _validate_claims
    self._validate_exp(payload, now, leeway)
  File "C:\Python27\lib\site-packages\jwt\api_jwt.py", line 176, in _validate_exp
    raise ExpiredSignatureError('Signature has expired')
ExpiredSignatureError: Signature has expired
2018-09-01 15:38:28,561 [exception:handle_uncaught_exception] [ERROR]- Internal Server Error: /listVipPerson/
Traceback (most recent call last):
  File "C:\Python27\lib\site-packages\django\core\handlers\exception.py", line 41, in inner
    response = get_response(request)
  File "C:\Python27\lib\site-packages\django\core\handlers\base.py", line 187, in _get_response
    response = self.process_exception_by_middleware(e, request)
  File "C:\Python27\lib\site-packages\django\core\handlers\base.py", line 185, in _get_response
    response = wrapped_callback(request, *callback_args, **callback_kwargs)
  File "D:/Study/VMS/vipMangementSystem\vms\views.py", line 27, in list_vip_person
    if jwt.verify_bearer_token(req.GET.get('access_token')):
  File "D:/Study/VMS/vipMangementSystem\vms\JWT.py", line 33, in verify_bearer_token
    payload = jwt.decode(token, 'mothanty',  algorithms=['HS256'])
  File "C:\Python27\lib\site-packages\jwt\api_jwt.py", line 105, in decode
    self._validate_claims(payload, merged_options, **kwargs)
  File "C:\Python27\lib\site-packages\jwt\api_jwt.py", line 135, in _validate_claims
    self._validate_exp(payload, now, leeway)
  File "C:\Python27\lib\site-packages\jwt\api_jwt.py", line 176, in _validate_exp
    raise ExpiredSignatureError('Signature has expired')
ExpiredSignatureError: Signature has expired
2018-09-01 15:38:31,227 [exception:handle_uncaught_exception] [ERROR]- Internal Server Error: /listVipPerson/
Traceback (most recent call last):
  File "C:\Python27\lib\site-packages\django\core\handlers\exception.py", line 41, in inner
    response = get_response(request)
  File "C:\Python27\lib\site-packages\django\core\handlers\base.py", line 187, in _get_response
    response = self.process_exception_by_middleware(e, request)
  File "C:\Python27\lib\site-packages\django\core\handlers\base.py", line 185, in _get_response
    response = wrapped_callback(request, *callback_args, **callback_kwargs)
  File "D:/Study/VMS/vipMangementSystem\vms\views.py", line 27, in list_vip_person
    if jwt.verify_bearer_token(req.GET.get('access_token')):
  File "D:/Study/VMS/vipMangementSystem\vms\JWT.py", line 33, in verify_bearer_token
    payload = jwt.decode(token, 'mothanty',  algorithms=['HS256'])
  File "C:\Python27\lib\site-packages\jwt\api_jwt.py", line 105, in decode
    self._validate_claims(payload, merged_options, **kwargs)
  File "C:\Python27\lib\site-packages\jwt\api_jwt.py", line 135, in _validate_claims
    self._validate_exp(payload, now, leeway)
  File "C:\Python27\lib\site-packages\jwt\api_jwt.py", line 176, in _validate_exp
    raise ExpiredSignatureError('Signature has expired')
ExpiredSignatureError: Signature has expired
2018-09-01 15:38:40,694 [exception:handle_uncaught_exception] [ERROR]- Internal Server Error: /listVipPerson/
Traceback (most recent call last):
  File "C:\Python27\lib\site-packages\django\core\handlers\exception.py", line 41, in inner
    response = get_response(request)
  File "C:\Python27\lib\site-packages\django\core\handlers\base.py", line 187, in _get_response
    response = self.process_exception_by_middleware(e, request)
  File "C:\Python27\lib\site-packages\django\core\handlers\base.py", line 185, in _get_response
    response = wrapped_callback(request, *callback_args, **callback_kwargs)
  File "D:/Study/VMS/vipMangementSystem\vms\views.py", line 27, in list_vip_person
    if jwt.verify_bearer_token(req.GET.get('access_token')):
  File "D:/Study/VMS/vipMangementSystem\vms\JWT.py", line 33, in verify_bearer_token
    payload = jwt.decode(token, 'mothanty',  algorithms=['HS256'])
  File "C:\Python27\lib\site-packages\jwt\api_jwt.py", line 105, in decode
    self._validate_claims(payload, merged_options, **kwargs)
  File "C:\Python27\lib\site-packages\jwt\api_jwt.py", line 135, in _validate_claims
    self._validate_exp(payload, now, leeway)
  File "C:\Python27\lib\site-packages\jwt\api_jwt.py", line 176, in _validate_exp
    raise ExpiredSignatureError('Signature has expired')
ExpiredSignatureError: Signature has expired
2018-09-01 15:38:48,727 [exception:handle_uncaught_exception] [ERROR]- Internal Server Error: /listVipPerson/
Traceback (most recent call last):
  File "C:\Python27\lib\site-packages\django\core\handlers\exception.py", line 41, in inner
    response = get_response(request)
  File "C:\Python27\lib\site-packages\django\core\handlers\base.py", line 187, in _get_response
    response = self.process_exception_by_middleware(e, request)
  File "C:\Python27\lib\site-packages\django\core\handlers\base.py", line 185, in _get_response
    response = wrapped_callback(request, *callback_args, **callback_kwargs)
  File "D:/Study/VMS/vipMangementSystem\vms\views.py", line 27, in list_vip_person
    if jwt.verify_bearer_token(req.GET.get('access_token')):
  File "D:/Study/VMS/vipMangementSystem\vms\JWT.py", line 33, in verify_bearer_token
    payload = jwt.decode(token, 'mothanty',  algorithms=['HS256'])
  File "C:\Python27\lib\site-packages\jwt\api_jwt.py", line 105, in decode
    self._validate_claims(payload, merged_options, **kwargs)
  File "C:\Python27\lib\site-packages\jwt\api_jwt.py", line 135, in _validate_claims
    self._validate_exp(payload, now, leeway)
  File "C:\Python27\lib\site-packages\jwt\api_jwt.py", line 176, in _validate_exp
    raise ExpiredSignatureError('Signature has expired')
ExpiredSignatureError: Signature has expired
2018-09-01 15:38:56,739 [exception:handle_uncaught_exception] [ERROR]- Internal Server Error: /listVipPerson/
Traceback (most recent call last):
  File "C:\Python27\lib\site-packages\django\core\handlers\exception.py", line 41, in inner
    response = get_response(request)
  File "C:\Python27\lib\site-packages\django\core\handlers\base.py", line 187, in _get_response
    response = self.process_exception_by_middleware(e, request)
  File "C:\Python27\lib\site-packages\django\core\handlers\base.py", line 185, in _get_response
    response = wrapped_callback(request, *callback_args, **callback_kwargs)
  File "D:/Study/VMS/vipMangementSystem\vms\views.py", line 27, in list_vip_person
    if jwt.verify_bearer_token(req.GET.get('access_token')):
  File "D:/Study/VMS/vipMangementSystem\vms\JWT.py", line 33, in verify_bearer_token
    payload = jwt.decode(token, 'mothanty',  algorithms=['HS256'])
  File "C:\Python27\lib\site-packages\jwt\api_jwt.py", line 105, in decode
    self._validate_claims(payload, merged_options, **kwargs)
  File "C:\Python27\lib\site-packages\jwt\api_jwt.py", line 135, in _validate_claims
    self._validate_exp(payload, now, leeway)
  File "C:\Python27\lib\site-packages\jwt\api_jwt.py", line 176, in _validate_exp
    raise ExpiredSignatureError('Signature has expired')
ExpiredSignatureError: Signature has expired
2018-09-01 15:38:58,983 [exception:handle_uncaught_exception] [ERROR]- Internal Server Error: /listVipPerson/
Traceback (most recent call last):
  File "C:\Python27\lib\site-packages\django\core\handlers\exception.py", line 41, in inner
    response = get_response(request)
  File "C:\Python27\lib\site-packages\django\core\handlers\base.py", line 187, in _get_response
    response = self.process_exception_by_middleware(e, request)
  File "C:\Python27\lib\site-packages\django\core\handlers\base.py", line 185, in _get_response
    response = wrapped_callback(request, *callback_args, **callback_kwargs)
  File "D:/Study/VMS/vipMangementSystem\vms\views.py", line 27, in list_vip_person
    if jwt.verify_bearer_token(req.GET.get('access_token')):
  File "D:/Study/VMS/vipMangementSystem\vms\JWT.py", line 33, in verify_bearer_token
    payload = jwt.decode(token, 'mothanty',  algorithms=['HS256'])
  File "C:\Python27\lib\site-packages\jwt\api_jwt.py", line 105, in decode
    self._validate_claims(payload, merged_options, **kwargs)
  File "C:\Python27\lib\site-packages\jwt\api_jwt.py", line 135, in _validate_claims
    self._validate_exp(payload, now, leeway)
  File "C:\Python27\lib\site-packages\jwt\api_jwt.py", line 176, in _validate_exp
    raise ExpiredSignatureError('Signature has expired')
ExpiredSignatureError: Signature has expired
2018-09-01 15:39:06,319 [exception:handle_uncaught_exception] [ERROR]- Internal Server Error: /listVipPerson/
Traceback (most recent call last):
  File "C:\Python27\lib\site-packages\django\core\handlers\exception.py", line 41, in inner
    response = get_response(request)
  File "C:\Python27\lib\site-packages\django\core\handlers\base.py", line 187, in _get_response
    response = self.process_exception_by_middleware(e, request)
  File "C:\Python27\lib\site-packages\django\core\handlers\base.py", line 185, in _get_response
    response = wrapped_callback(request, *callback_args, **callback_kwargs)
  File "D:/Study/VMS/vipMangementSystem\vms\views.py", line 27, in list_vip_person
    if jwt.verify_bearer_token(req.GET.get('access_token')):
  File "D:/Study/VMS/vipMangementSystem\vms\JWT.py", line 33, in verify_bearer_token
    payload = jwt.decode(token, 'mothanty',  algorithms=['HS256'])
  File "C:\Python27\lib\site-packages\jwt\api_jwt.py", line 105, in decode
    self._validate_claims(payload, merged_options, **kwargs)
  File "C:\Python27\lib\site-packages\jwt\api_jwt.py", line 135, in _validate_claims
    self._validate_exp(payload, now, leeway)
  File "C:\Python27\lib\site-packages\jwt\api_jwt.py", line 176, in _validate_exp
    raise ExpiredSignatureError('Signature has expired')
ExpiredSignatureError: Signature has expired
2018-09-01 15:39:21,706 [exception:handle_uncaught_exception] [ERROR]- Internal Server Error: /listVipPerson/
Traceback (most recent call last):
  File "C:\Python27\lib\site-packages\django\core\handlers\exception.py", line 41, in inner
    response = get_response(request)
  File "C:\Python27\lib\site-packages\django\core\handlers\base.py", line 187, in _get_response
    response = self.process_exception_by_middleware(e, request)
  File "C:\Python27\lib\site-packages\django\core\handlers\base.py", line 185, in _get_response
    response = wrapped_callback(request, *callback_args, **callback_kwargs)
  File "D:/Study/VMS/vipMangementSystem\vms\views.py", line 27, in list_vip_person
    if jwt.verify_bearer_token(req.GET.get('access_token')):
  File "D:/Study/VMS/vipMangementSystem\vms\JWT.py", line 33, in verify_bearer_token
    payload = jwt.decode(token, 'mothanty',  algorithms=['HS256'])
  File "C:\Python27\lib\site-packages\jwt\api_jwt.py", line 105, in decode
    self._validate_claims(payload, merged_options, **kwargs)
  File "C:\Python27\lib\site-packages\jwt\api_jwt.py", line 135, in _validate_claims
    self._validate_exp(payload, now, leeway)
  File "C:\Python27\lib\site-packages\jwt\api_jwt.py", line 176, in _validate_exp
    raise ExpiredSignatureError('Signature has expired')
ExpiredSignatureError: Signature has expired
2018-09-01 15:39:26,844 [exception:handle_uncaught_exception] [ERROR]- Internal Server Error: /listVipPerson/
Traceback (most recent call last):
  File "C:\Python27\lib\site-packages\django\core\handlers\exception.py", line 41, in inner
    response = get_response(request)
  File "C:\Python27\lib\site-packages\django\core\handlers\base.py", line 187, in _get_response
    response = self.process_exception_by_middleware(e, request)
  File "C:\Python27\lib\site-packages\django\core\handlers\base.py", line 185, in _get_response
    response = wrapped_callback(request, *callback_args, **callback_kwargs)
  File "D:/Study/VMS/vipMangementSystem\vms\views.py", line 27, in list_vip_person
    if jwt.verify_bearer_token(req.GET.get('access_token')):
  File "D:/Study/VMS/vipMangementSystem\vms\JWT.py", line 33, in verify_bearer_token
    payload = jwt.decode(token, 'mothanty',  algorithms=['HS256'])
  File "C:\Python27\lib\site-packages\jwt\api_jwt.py", line 105, in decode
    self._validate_claims(payload, merged_options, **kwargs)
  File "C:\Python27\lib\site-packages\jwt\api_jwt.py", line 135, in _validate_claims
    self._validate_exp(payload, now, leeway)
  File "C:\Python27\lib\site-packages\jwt\api_jwt.py", line 176, in _validate_exp
    raise ExpiredSignatureError('Signature has expired')
ExpiredSignatureError: Signature has expired
2018-09-01 17:04:28,515 [exception:handle_uncaught_exception] [ERROR]- Internal Server Error: /listVipPerson/
Traceback (most recent call last):
  File "C:\Python27\lib\site-packages\django\core\handlers\exception.py", line 41, in inner
    response = get_response(request)
  File "C:\Python27\lib\site-packages\django\core\handlers\base.py", line 187, in _get_response
    response = self.process_exception_by_middleware(e, request)
  File "C:\Python27\lib\site-packages\django\core\handlers\base.py", line 185, in _get_response
    response = wrapped_callback(request, *callback_args, **callback_kwargs)
  File "D:/Study/VMS/vipMangementSystem\vms\views.py", line 27, in list_vip_person
    if jwt.verify_bearer_token(req.GET.get('access_token')):
  File "D:/Study/VMS/vipMangementSystem\vms\JWT.py", line 34, in verify_bearer_token
    result = db.getAll("select * from t_token where token = '111' and DATE_SUB(now(), INTERVAL 10 SECOND)>time"%token)
TypeError: not all arguments converted during string formatting
2018-09-01 17:04:31,214 [exception:handle_uncaught_exception] [ERROR]- Internal Server Error: /listVipPerson/
Traceback (most recent call last):
  File "C:\Python27\lib\site-packages\django\core\handlers\exception.py", line 41, in inner
    response = get_response(request)
  File "C:\Python27\lib\site-packages\django\core\handlers\base.py", line 187, in _get_response
    response = self.process_exception_by_middleware(e, request)
  File "C:\Python27\lib\site-packages\django\core\handlers\base.py", line 185, in _get_response
    response = wrapped_callback(request, *callback_args, **callback_kwargs)
  File "D:/Study/VMS/vipMangementSystem\vms\views.py", line 27, in list_vip_person
    if jwt.verify_bearer_token(req.GET.get('access_token')):
  File "D:/Study/VMS/vipMangementSystem\vms\JWT.py", line 34, in verify_bearer_token
    result = db.getAll("select * from t_token where token = '111' and DATE_SUB(now(), INTERVAL 10 SECOND)>time"%token)
TypeError: not all arguments converted during string formatting
2018-09-01 17:05:19,648 [exception:handle_uncaught_exception] [ERROR]- Internal Server Error: /listVipPerson/
Traceback (most recent call last):
  File "C:\Python27\lib\site-packages\django\core\handlers\exception.py", line 41, in inner
    response = get_response(request)
  File "C:\Python27\lib\site-packages\django\core\handlers\base.py", line 187, in _get_response
    response = self.process_exception_by_middleware(e, request)
  File "C:\Python27\lib\site-packages\django\core\handlers\base.py", line 185, in _get_response
    response = wrapped_callback(request, *callback_args, **callback_kwargs)
  File "D:/Study/VMS/vipMangementSystem\vms\views.py", line 27, in list_vip_person
    if jwt.verify_bearer_token(req.GET.get('access_token')):
  File "D:/Study/VMS/vipMangementSystem\vms\JWT.py", line 34, in verify_bearer_token
    result = db.getAll("select * from t_token where token = '111' and DATE_SUB(now(), INTERVAL 10 SECOND)>time"%token)
TypeError: not all arguments converted during string formatting
2018-09-01 17:05:50,668 [exception:handle_uncaught_exception] [ERROR]- Internal Server Error: /listVipPerson/
Traceback (most recent call last):
  File "C:\Python27\lib\site-packages\django\core\handlers\exception.py", line 41, in inner
    response = get_response(request)
  File "C:\Python27\lib\site-packages\django\core\handlers\base.py", line 187, in _get_response
    response = self.process_exception_by_middleware(e, request)
  File "C:\Python27\lib\site-packages\django\core\handlers\base.py", line 185, in _get_response
    response = wrapped_callback(request, *callback_args, **callback_kwargs)
  File "D:/Study/VMS/vipMangementSystem\vms\views.py", line 27, in list_vip_person
    if jwt.verify_bearer_token(req.GET.get('access_token')):
  File "D:/Study/VMS/vipMangementSystem\vms\JWT.py", line 34, in verify_bearer_token
    result = db.getAll("select * from t_token where token = '111' and DATE_SUB(now(), INTERVAL 10 SECOND)>time"%token)
TypeError: not all arguments converted during string formatting
2018-09-01 17:06:06,030 [exception:handle_uncaught_exception] [ERROR]- Internal Server Error: /listVipPerson/
Traceback (most recent call last):
  File "C:\Python27\lib\site-packages\django\core\handlers\exception.py", line 41, in inner
    response = get_response(request)
  File "C:\Python27\lib\site-packages\django\core\handlers\base.py", line 187, in _get_response
    response = self.process_exception_by_middleware(e, request)
  File "C:\Python27\lib\site-packages\django\core\handlers\base.py", line 185, in _get_response
    response = wrapped_callback(request, *callback_args, **callback_kwargs)
  File "D:/Study/VMS/vipMangementSystem\vms\views.py", line 27, in list_vip_person
    if jwt.verify_bearer_token(req.GET.get('access_token')):
  File "D:/Study/VMS/vipMangementSystem\vms\JWT.py", line 34, in verify_bearer_token
    result = db.getAll("select * from t_token where token = '111' and DATE_SUB(now(), INTERVAL 10 SECOND)>time"%token)
TypeError: not all arguments converted during string formatting
2018-09-01 17:06:30,631 [exception:handle_uncaught_exception] [ERROR]- Internal Server Error: /listVipPerson/
Traceback (most recent call last):
  File "C:\Python27\lib\site-packages\django\core\handlers\exception.py", line 41, in inner
    response = get_response(request)
  File "C:\Python27\lib\site-packages\django\core\handlers\base.py", line 187, in _get_response
    response = self.process_exception_by_middleware(e, request)
  File "C:\Python27\lib\site-packages\django\core\handlers\base.py", line 185, in _get_response
    response = wrapped_callback(request, *callback_args, **callback_kwargs)
  File "D:/Study/VMS/vipMangementSystem\vms\views.py", line 27, in list_vip_person
    if jwt.verify_bearer_token(req.GET.get('access_token')):
  File "D:/Study/VMS/vipMangementSystem\vms\JWT.py", line 34, in verify_bearer_token
    result = db.getAll("select * from t_token where token = '111' and DATE_SUB(now(), INTERVAL 10 SECOND)>time"%token)
TypeError: not all arguments converted during string formatting
2018-09-01 17:06:36,035 [exception:handle_uncaught_exception] [ERROR]- Internal Server Error: /listVipPerson/
Traceback (most recent call last):
  File "C:\Python27\lib\site-packages\django\core\handlers\exception.py", line 41, in inner
    response = get_response(request)
  File "C:\Python27\lib\site-packages\django\core\handlers\base.py", line 187, in _get_response
    response = self.process_exception_by_middleware(e, request)
  File "C:\Python27\lib\site-packages\django\core\handlers\base.py", line 185, in _get_response
    response = wrapped_callback(request, *callback_args, **callback_kwargs)
  File "D:/Study/VMS/vipMangementSystem\vms\views.py", line 27, in list_vip_person
    if jwt.verify_bearer_token(req.GET.get('access_token')):
  File "D:/Study/VMS/vipMangementSystem\vms\JWT.py", line 34, in verify_bearer_token
    result = db.getAll("select * from t_token where token = '111' and DATE_SUB(now(), INTERVAL 10 SECOND)>time"%token)
TypeError: not all arguments converted during string formatting
2018-09-01 17:06:51,621 [exception:handle_uncaught_exception] [ERROR]- Internal Server Error: /listVipPerson/
Traceback (most recent call last):
  File "C:\Python27\lib\site-packages\django\core\handlers\exception.py", line 41, in inner
    response = get_response(request)
  File "C:\Python27\lib\site-packages\django\core\handlers\base.py", line 187, in _get_response
    response = self.process_exception_by_middleware(e, request)
  File "C:\Python27\lib\site-packages\django\core\handlers\base.py", line 185, in _get_response
    response = wrapped_callback(request, *callback_args, **callback_kwargs)
  File "D:/Study/VMS/vipMangementSystem\vms\views.py", line 27, in list_vip_person
    if jwt.verify_bearer_token(req.GET.get('access_token')):
  File "D:/Study/VMS/vipMangementSystem\vms\JWT.py", line 34, in verify_bearer_token
    result = db.getAll("select * from t_token where token = '111' and DATE_SUB(now(), INTERVAL 10 SECOND)>time"%token)
TypeError: not all arguments converted during string formatting
2018-09-01 17:07:17,377 [exception:handle_uncaught_exception] [ERROR]- Internal Server Error: /listVipPerson/
Traceback (most recent call last):
  File "C:\Python27\lib\site-packages\django\core\handlers\exception.py", line 41, in inner
    response = get_response(request)
  File "C:\Python27\lib\site-packages\django\core\handlers\base.py", line 187, in _get_response
    response = self.process_exception_by_middleware(e, request)
  File "C:\Python27\lib\site-packages\django\core\handlers\base.py", line 185, in _get_response
    response = wrapped_callback(request, *callback_args, **callback_kwargs)
  File "D:/Study/VMS/vipMangementSystem\vms\views.py", line 27, in list_vip_person
    if jwt.verify_bearer_token(req.GET.get('access_token')):
  File "D:/Study/VMS/vipMangementSystem\vms\JWT.py", line 34, in verify_bearer_token
    result = db.getAll("select * from t_token where token = '111' and DATE_SUB(now(), INTERVAL 10 SECOND)>time"%token)
TypeError: not all arguments converted during string formatting
2018-09-01 17:24:58,051 [exception:handle_uncaught_exception] [ERROR]- Internal Server Error: /listVipPerson/
Traceback (most recent call last):
  File "C:\Python27\lib\site-packages\django\core\handlers\exception.py", line 41, in inner
    response = get_response(request)
  File "C:\Python27\lib\site-packages\django\core\handlers\base.py", line 187, in _get_response
    response = self.process_exception_by_middleware(e, request)
  File "C:\Python27\lib\site-packages\django\core\handlers\base.py", line 185, in _get_response
    response = wrapped_callback(request, *callback_args, **callback_kwargs)
  File "D:/Study/VMS/vipMangementSystem\vms\views.py", line 27, in list_vip_person
    if jwt.verify_bearer_token(req.GET.get('access_token')):
  File "D:/Study/VMS/vipMangementSystem\vms\JWT.py", line 32, in verify_bearer_token
    payload = jwt.decode(token, 'mothanty',  algorithms=['HS256'])
  File "C:\Python27\lib\site-packages\jwt\api_jwt.py", line 105, in decode
    self._validate_claims(payload, merged_options, **kwargs)
  File "C:\Python27\lib\site-packages\jwt\api_jwt.py", line 135, in _validate_claims
    self._validate_exp(payload, now, leeway)
  File "C:\Python27\lib\site-packages\jwt\api_jwt.py", line 176, in _validate_exp
    raise ExpiredSignatureError('Signature has expired')
ExpiredSignatureError: Signature has expired
2018-09-01 17:25:00,434 [exception:handle_uncaught_exception] [ERROR]- Internal Server Error: /listVipPerson/
Traceback (most recent call last):
  File "C:\Python27\lib\site-packages\django\core\handlers\exception.py", line 41, in inner
    response = get_response(request)
  File "C:\Python27\lib\site-packages\django\core\handlers\base.py", line 187, in _get_response
    response = self.process_exception_by_middleware(e, request)
  File "C:\Python27\lib\site-packages\django\core\handlers\base.py", line 185, in _get_response
    response = wrapped_callback(request, *callback_args, **callback_kwargs)
  File "D:/Study/VMS/vipMangementSystem\vms\views.py", line 27, in list_vip_person
    if jwt.verify_bearer_token(req.GET.get('access_token')):
  File "D:/Study/VMS/vipMangementSystem\vms\JWT.py", line 32, in verify_bearer_token
    payload = jwt.decode(token, 'mothanty',  algorithms=['HS256'])
  File "C:\Python27\lib\site-packages\jwt\api_jwt.py", line 105, in decode
    self._validate_claims(payload, merged_options, **kwargs)
  File "C:\Python27\lib\site-packages\jwt\api_jwt.py", line 135, in _validate_claims
    self._validate_exp(payload, now, leeway)
  File "C:\Python27\lib\site-packages\jwt\api_jwt.py", line 176, in _validate_exp
    raise ExpiredSignatureError('Signature has expired')
ExpiredSignatureError: Signature has expired
2018-09-01 17:25:40,440 [exception:handle_uncaught_exception] [ERROR]- Internal Server Error: /listVipPerson/
Traceback (most recent call last):
  File "C:\Python27\lib\site-packages\django\core\handlers\exception.py", line 41, in inner
    response = get_response(request)
  File "C:\Python27\lib\site-packages\django\core\handlers\base.py", line 187, in _get_response
    response = self.process_exception_by_middleware(e, request)
  File "C:\Python27\lib\site-packages\django\core\handlers\base.py", line 185, in _get_response
    response = wrapped_callback(request, *callback_args, **callback_kwargs)
  File "D:/Study/VMS/vipMangementSystem\vms\views.py", line 27, in list_vip_person
    if jwt.verify_bearer_token(req.GET.get('access_token')):
  File "D:/Study/VMS/vipMangementSystem\vms\JWT.py", line 32, in verify_bearer_token
    payload = jwt.decode(token, 'mothanty',  algorithms=['HS256'])
  File "C:\Python27\lib\site-packages\jwt\api_jwt.py", line 105, in decode
    self._validate_claims(payload, merged_options, **kwargs)
  File "C:\Python27\lib\site-packages\jwt\api_jwt.py", line 135, in _validate_claims
    self._validate_exp(payload, now, leeway)
  File "C:\Python27\lib\site-packages\jwt\api_jwt.py", line 176, in _validate_exp
    raise ExpiredSignatureError('Signature has expired')
ExpiredSignatureError: Signature has expired
2018-09-01 17:25:56,904 [exception:handle_uncaught_exception] [ERROR]- Internal Server Error: /listVipPerson/
Traceback (most recent call last):
  File "C:\Python27\lib\site-packages\django\core\handlers\exception.py", line 41, in inner
    response = get_response(request)
  File "C:\Python27\lib\site-packages\django\core\handlers\base.py", line 187, in _get_response
    response = self.process_exception_by_middleware(e, request)
  File "C:\Python27\lib\site-packages\django\core\handlers\base.py", line 185, in _get_response
    response = wrapped_callback(request, *callback_args, **callback_kwargs)
  File "D:/Study/VMS/vipMangementSystem\vms\views.py", line 27, in list_vip_person
    if jwt.verify_bearer_token(req.GET.get('access_token')):
  File "D:/Study/VMS/vipMangementSystem\vms\JWT.py", line 32, in verify_bearer_token
    payload = jwt.decode(token, 'mothanty',  algorithms=['HS256'])
  File "C:\Python27\lib\site-packages\jwt\api_jwt.py", line 105, in decode
    self._validate_claims(payload, merged_options, **kwargs)
  File "C:\Python27\lib\site-packages\jwt\api_jwt.py", line 135, in _validate_claims
    self._validate_exp(payload, now, leeway)
  File "C:\Python27\lib\site-packages\jwt\api_jwt.py", line 176, in _validate_exp
    raise ExpiredSignatureError('Signature has expired')
ExpiredSignatureError: Signature has expired
2018-09-01 17:27:01,207 [exception:handle_uncaught_exception] [ERROR]- Internal Server Error: /listVipPerson/
Traceback (most recent call last):
  File "C:\Python27\lib\site-packages\django\core\handlers\exception.py", line 41, in inner
    response = get_response(request)
  File "C:\Python27\lib\site-packages\django\core\handlers\base.py", line 187, in _get_response
    response = self.process_exception_by_middleware(e, request)
  File "C:\Python27\lib\site-packages\django\core\handlers\base.py", line 185, in _get_response
    response = wrapped_callback(request, *callback_args, **callback_kwargs)
  File "D:/Study/VMS/vipMangementSystem\vms\views.py", line 27, in list_vip_person
    if jwt.verify_bearer_token(req.GET.get('access_token')):
  File "D:/Study/VMS/vipMangementSystem\vms\JWT.py", line 32, in verify_bearer_token
    payload = jwt.decode(token, 'mothanty',  algorithms=['HS256'])
  File "C:\Python27\lib\site-packages\jwt\api_jwt.py", line 105, in decode
    self._validate_claims(payload, merged_options, **kwargs)
  File "C:\Python27\lib\site-packages\jwt\api_jwt.py", line 135, in _validate_claims
    self._validate_exp(payload, now, leeway)
  File "C:\Python27\lib\site-packages\jwt\api_jwt.py", line 176, in _validate_exp
    raise ExpiredSignatureError('Signature has expired')
ExpiredSignatureError: Signature has expired
2018-09-01 17:27:29,132 [exception:handle_uncaught_exception] [ERROR]- Internal Server Error: /listVipPerson/
Traceback (most recent call last):
  File "C:\Python27\lib\site-packages\django\core\handlers\exception.py", line 41, in inner
    response = get_response(request)
  File "C:\Python27\lib\site-packages\django\core\handlers\base.py", line 187, in _get_response
    response = self.process_exception_by_middleware(e, request)
  File "C:\Python27\lib\site-packages\django\core\handlers\base.py", line 185, in _get_response
    response = wrapped_callback(request, *callback_args, **callback_kwargs)
  File "D:/Study/VMS/vipMangementSystem\vms\views.py", line 27, in list_vip_person
    if jwt.verify_bearer_token(req.GET.get('access_token')):
  File "D:/Study/VMS/vipMangementSystem\vms\JWT.py", line 32, in verify_bearer_token
    payload = jwt.decode(token, 'mothanty',  algorithms=['HS256'])
  File "C:\Python27\lib\site-packages\jwt\api_jwt.py", line 105, in decode
    self._validate_claims(payload, merged_options, **kwargs)
  File "C:\Python27\lib\site-packages\jwt\api_jwt.py", line 135, in _validate_claims
    self._validate_exp(payload, now, leeway)
  File "C:\Python27\lib\site-packages\jwt\api_jwt.py", line 176, in _validate_exp
    raise ExpiredSignatureError('Signature has expired')
ExpiredSignatureError: Signature has expired
2018-09-01 17:32:49,240 [exception:handle_uncaught_exception] [ERROR]- Internal Server Error: /listVipPerson/
Traceback (most recent call last):
  File "C:\Python27\lib\site-packages\django\core\handlers\exception.py", line 41, in inner
    response = get_response(request)
  File "C:\Python27\lib\site-packages\django\core\handlers\base.py", line 187, in _get_response
    response = self.process_exception_by_middleware(e, request)
  File "C:\Python27\lib\site-packages\django\core\handlers\base.py", line 185, in _get_response
    response = wrapped_callback(request, *callback_args, **callback_kwargs)
  File "D:/Study/VMS/vipMangementSystem\vms\views.py", line 27, in list_vip_person
    if jwt.verify_bearer_token(req.GET.get('access_token')):
  File "D:/Study/VMS/vipMangementSystem\vms\JWT.py", line 32, in verify_bearer_token
    payload = jwt.decode(token, 'mothanty',  algorithms=['HS256'])
  File "C:\Python27\lib\site-packages\jwt\api_jwt.py", line 105, in decode
    self._validate_claims(payload, merged_options, **kwargs)
  File "C:\Python27\lib\site-packages\jwt\api_jwt.py", line 135, in _validate_claims
    self._validate_exp(payload, now, leeway)
  File "C:\Python27\lib\site-packages\jwt\api_jwt.py", line 176, in _validate_exp
    raise ExpiredSignatureError('Signature has expired')
ExpiredSignatureError: Signature has expired
2018-09-01 18:02:55,230 [base:get_response] [WARNING]- Not Found: /managerLogout/
2018-09-01 18:03:29,263 [base:get_response] [WARNING]- Not Found: /managerLogout/
2018-09-01 18:15:11,200 [base:get_response] [WARNING]- Not Found: /managerLogout/
2018-09-02 16:25:48,770 [exception:handle_uncaught_exception] [ERROR]- Internal Server Error: /listVipPerson/
Traceback (most recent call last):
  File "C:\Python27\lib\site-packages\django\core\handlers\exception.py", line 41, in inner
    response = get_response(request)
  File "C:\Python27\lib\site-packages\django\core\handlers\base.py", line 198, in _get_response
    "returned None instead." % (callback.__module__, view_name)
ValueError: The view vms.JWT.wrapper didn't return an HttpResponse object. It returned None instead.
2018-09-02 16:26:23,453 [exception:handle_uncaught_exception] [ERROR]- Internal Server Error: /listVipPerson/
Traceback (most recent call last):
  File "C:\Python27\lib\site-packages\django\core\handlers\exception.py", line 41, in inner
    response = get_response(request)
  File "C:\Python27\lib\site-packages\django\core\handlers\base.py", line 198, in _get_response
    "returned None instead." % (callback.__module__, view_name)
ValueError: The view vms.JWT.wrapper didn't return an HttpResponse object. It returned None instead.
2018-09-02 16:26:28,089 [exception:handle_uncaught_exception] [ERROR]- Internal Server Error: /listVipPerson/
Traceback (most recent call last):
  File "C:\Python27\lib\site-packages\django\core\handlers\exception.py", line 41, in inner
    response = get_response(request)
  File "C:\Python27\lib\site-packages\django\core\handlers\base.py", line 198, in _get_response
    "returned None instead." % (callback.__module__, view_name)
ValueError: The view vms.JWT.wrapper didn't return an HttpResponse object. It returned None instead.
2018-09-02 16:26:42,437 [exception:handle_uncaught_exception] [ERROR]- Internal Server Error: /listVipPerson/
Traceback (most recent call last):
  File "C:\Python27\lib\site-packages\django\core\handlers\exception.py", line 41, in inner
    response = get_response(request)
  File "C:\Python27\lib\site-packages\django\core\handlers\base.py", line 198, in _get_response
    "returned None instead." % (callback.__module__, view_name)
ValueError: The view vms.JWT.wrapper didn't return an HttpResponse object. It returned None instead.
2018-09-02 16:27:16,546 [exception:handle_uncaught_exception] [ERROR]- Internal Server Error: /listVipPerson/
Traceback (most recent call last):
  File "C:\Python27\lib\site-packages\django\core\handlers\exception.py", line 41, in inner
    response = get_response(request)
  File "C:\Python27\lib\site-packages\django\core\handlers\base.py", line 198, in _get_response
    "returned None instead." % (callback.__module__, view_name)
ValueError: The view vms.JWT.wrapper didn't return an HttpResponse object. It returned None instead.
2018-09-02 16:29:23,443 [exception:handle_uncaught_exception] [ERROR]- Internal Server Error: /listVipPerson/
Traceback (most recent call last):
  File "C:\Python27\lib\site-packages\django\core\handlers\exception.py", line 41, in inner
    response = get_response(request)
  File "C:\Python27\lib\site-packages\django\core\handlers\base.py", line 198, in _get_response
    "returned None instead." % (callback.__module__, view_name)
ValueError: The view vms.views.wrapper didn't return an HttpResponse object. It returned None instead.
2018-09-02 16:29:31,075 [exception:handle_uncaught_exception] [ERROR]- Internal Server Error: /listVipPerson/
Traceback (most recent call last):
  File "C:\Python27\lib\site-packages\django\core\handlers\exception.py", line 41, in inner
    response = get_response(request)
  File "C:\Python27\lib\site-packages\django\core\handlers\base.py", line 198, in _get_response
    "returned None instead." % (callback.__module__, view_name)
ValueError: The view vms.views.wrapper didn't return an HttpResponse object. It returned None instead.
2018-09-02 16:29:33,582 [exception:handle_uncaught_exception] [ERROR]- Internal Server Error: /listVipPerson/
Traceback (most recent call last):
  File "C:\Python27\lib\site-packages\django\core\handlers\exception.py", line 41, in inner
    response = get_response(request)
  File "C:\Python27\lib\site-packages\django\core\handlers\base.py", line 198, in _get_response
    "returned None instead." % (callback.__module__, view_name)
ValueError: The view vms.views.wrapper didn't return an HttpResponse object. It returned None instead.
2018-09-02 16:30:28,782 [exception:handle_uncaught_exception] [ERROR]- Internal Server Error: /listVipPerson/
Traceback (most recent call last):
  File "C:\Python27\lib\site-packages\django\core\handlers\exception.py", line 41, in inner
    response = get_response(request)
  File "C:\Python27\lib\site-packages\django\core\handlers\base.py", line 198, in _get_response
    "returned None instead." % (callback.__module__, view_name)
ValueError: The view vms.views.wrapper didn't return an HttpResponse object. It returned None instead.
2018-09-02 16:35:15,128 [exception:handle_uncaught_exception] [ERROR]- Internal Server Error: /listVipPerson/
Traceback (most recent call last):
  File "C:\Python27\lib\site-packages\django\core\handlers\exception.py", line 41, in inner
    response = get_response(request)
  File "C:\Python27\lib\site-packages\django\core\handlers\base.py", line 187, in _get_response
    response = self.process_exception_by_middleware(e, request)
  File "C:\Python27\lib\site-packages\django\core\handlers\base.py", line 185, in _get_response
    response = wrapped_callback(request, *callback_args, **callback_kwargs)
  File "D:\Study\VMS\vipMangementSystem\vms\views.py", line 23, in wrapper
    func()
TypeError: list_vip_person() takes exactly 1 argument (0 given)
2018-09-02 16:36:47,436 [exception:handle_uncaught_exception] [ERROR]- Internal Server Error: /listVipPerson/
Traceback (most recent call last):
  File "C:\Python27\lib\site-packages\django\core\handlers\exception.py", line 41, in inner
    response = get_response(request)
  File "C:\Python27\lib\site-packages\django\core\handlers\base.py", line 198, in _get_response
    "returned None instead." % (callback.__module__, view_name)
ValueError: The view vms.views.wrapper didn't return an HttpResponse object. It returned None instead.
2018-09-02 16:41:51,605 [exception:handle_uncaught_exception] [ERROR]- Internal Server Error: /listVipPerson/
Traceback (most recent call last):
  File "C:\Python27\lib\site-packages\django\core\handlers\exception.py", line 41, in inner
    response = get_response(request)
  File "C:\Python27\lib\site-packages\django\core\handlers\base.py", line 187, in _get_response
    response = self.process_exception_by_middleware(e, request)
  File "C:\Python27\lib\site-packages\django\core\handlers\base.py", line 185, in _get_response
    response = wrapped_callback(request, *callback_args, **callback_kwargs)
TypeError: inner_function() takes no arguments (1 given)
2018-09-02 16:41:58,512 [exception:handle_uncaught_exception] [ERROR]- Internal Server Error: /listVipPerson/
Traceback (most recent call last):
  File "C:\Python27\lib\site-packages\django\core\handlers\exception.py", line 41, in inner
    response = get_response(request)
  File "C:\Python27\lib\site-packages\django\core\handlers\base.py", line 187, in _get_response
    response = self.process_exception_by_middleware(e, request)
  File "C:\Python27\lib\site-packages\django\core\handlers\base.py", line 185, in _get_response
    response = wrapped_callback(request, *callback_args, **callback_kwargs)
TypeError: inner_function() takes no arguments (1 given)
2018-09-02 20:31:02,206 [exception:handle_uncaught_exception] [ERROR]- Internal Server Error: /delVipPerson/
Traceback (most recent call last):
  File "C:\Python27\lib\site-packages\django\core\handlers\exception.py", line 41, in inner
    response = get_response(request)
  File "C:\Python27\lib\site-packages\django\core\handlers\base.py", line 187, in _get_response
    response = self.process_exception_by_middleware(e, request)
  File "C:\Python27\lib\site-packages\django\core\handlers\base.py", line 185, in _get_response
    response = wrapped_callback(request, *callback_args, **callback_kwargs)
  File "D:\Study\VMS\vipMangementSystem\vms\views.py", line 168, in del_vip_person
    if jwt.verify_bearer_token(req.POST.get('access_token')):
  File "D:\Study\VMS\vipMangementSystem\vms\JWT.py", line 43, in verify_bearer_token
    payload = jwt.decode(token, 'mothanty',  algorithms=['HS256'])
  File "C:\Python27\lib\site-packages\jwt\api_jwt.py", line 85, in decode
    payload, _, _, _ = self._load(jwt)
  File "C:\Python27\lib\site-packages\jwt\api_jws.py", line 178, in _load
    binary_type))
DecodeError: Invalid token type. Token must be a <type 'str'>
2018-09-02 20:40:25,211 [exception:handle_uncaught_exception] [ERROR]- Internal Server Error: /listVipPerson/
Traceback (most recent call last):
  File "C:\Python27\lib\site-packages\django\core\handlers\exception.py", line 41, in inner
    response = get_response(request)
  File "C:\Python27\lib\site-packages\django\core\handlers\base.py", line 187, in _get_response
    response = self.process_exception_by_middleware(e, request)
  File "C:\Python27\lib\site-packages\django\core\handlers\base.py", line 185, in _get_response
    response = wrapped_callback(request, *callback_args, **callback_kwargs)
  File "D:\Study\VMS\vipMangementSystem\vms\JWT.py", line 50, in __deco
    payload = jwt.decode(request.method.get('access_token'), 'mothanty', algorithms=['HS256'])
AttributeError: 'str' object has no attribute 'get'
2018-09-02 20:41:07,497 [exception:handle_uncaught_exception] [ERROR]- Internal Server Error: /listVipPerson/
Traceback (most recent call last):
  File "C:\Python27\lib\site-packages\django\core\handlers\exception.py", line 41, in inner
    response = get_response(request)
  File "C:\Python27\lib\site-packages\django\core\handlers\base.py", line 187, in _get_response
    response = self.process_exception_by_middleware(e, request)
  File "C:\Python27\lib\site-packages\django\core\handlers\base.py", line 185, in _get_response
    response = wrapped_callback(request, *callback_args, **callback_kwargs)
  File "D:\Study\VMS\vipMangementSystem\vms\JWT.py", line 51, in __deco
    payload = jwt.decode(request.method.get('access_token'), 'mothanty', algorithms=['HS256'])
AttributeError: 'str' object has no attribute 'get'
2018-09-02 20:41:21,190 [exception:handle_uncaught_exception] [ERROR]- Internal Server Error: /listVipPerson/
Traceback (most recent call last):
  File "C:\Python27\lib\site-packages\django\core\handlers\exception.py", line 41, in inner
    response = get_response(request)
  File "C:\Python27\lib\site-packages\django\core\handlers\base.py", line 187, in _get_response
    response = self.process_exception_by_middleware(e, request)
  File "C:\Python27\lib\site-packages\django\core\handlers\base.py", line 185, in _get_response
    response = wrapped_callback(request, *callback_args, **callback_kwargs)
  File "D:\Study\VMS\vipMangementSystem\vms\JWT.py", line 54, in __deco
    "select * from t_token where token = '%s' and DATE_SUB(now(), INTERVAL 1 HOUR)<time" % token)
NameError: global name 'token' is not defined
2018-09-02 20:41:23,286 [exception:handle_uncaught_exception] [ERROR]- Internal Server Error: /listVipPerson/
Traceback (most recent call last):
  File "C:\Python27\lib\site-packages\django\core\handlers\exception.py", line 41, in inner
    response = get_response(request)
  File "C:\Python27\lib\site-packages\django\core\handlers\base.py", line 187, in _get_response
    response = self.process_exception_by_middleware(e, request)
  File "C:\Python27\lib\site-packages\django\core\handlers\base.py", line 185, in _get_response
    response = wrapped_callback(request, *callback_args, **callback_kwargs)
  File "D:\Study\VMS\vipMangementSystem\vms\JWT.py", line 54, in __deco
    "select * from t_token where token = '%s' and DATE_SUB(now(), INTERVAL 1 HOUR)<time" % token)
NameError: global name 'token' is not defined
2018-09-02 20:44:15,201 [exception:handle_uncaught_exception] [ERROR]- Internal Server Error: /listVipPerson/
Traceback (most recent call last):
  File "C:\Python27\lib\site-packages\django\core\handlers\exception.py", line 41, in inner
    response = get_response(request)
  File "C:\Python27\lib\site-packages\django\core\handlers\base.py", line 187, in _get_response
    response = self.process_exception_by_middleware(e, request)
  File "C:\Python27\lib\site-packages\django\core\handlers\base.py", line 185, in _get_response
    response = wrapped_callback(request, *callback_args, **callback_kwargs)
  File "D:\Study\VMS\vipMangementSystem\vms\JWT.py", line 55, in __deco
    payload = jwt.decode(token, '1', algorithms=['HS256'])
  File "C:\Python27\lib\site-packages\jwt\api_jwt.py", line 93, in decode
    jwt, key=key, algorithms=algorithms, options=options, **kwargs
  File "C:\Python27\lib\site-packages\jwt\api_jws.py", line 157, in decode
    key, algorithms)
  File "C:\Python27\lib\site-packages\jwt\api_jws.py", line 224, in _verify_signature
    raise InvalidSignatureError('Signature verification failed')
InvalidSignatureError: Signature verification failed
2018-09-02 20:46:16,900 [exception:handle_uncaught_exception] [ERROR]- Internal Server Error: /listVipPerson/
Traceback (most recent call last):
  File "C:\Python27\lib\site-packages\django\core\handlers\exception.py", line 41, in inner
    response = get_response(request)
  File "C:\Python27\lib\site-packages\django\core\handlers\base.py", line 187, in _get_response
    response = self.process_exception_by_middleware(e, request)
  File "C:\Python27\lib\site-packages\django\core\handlers\base.py", line 185, in _get_response
    response = wrapped_callback(request, *callback_args, **callback_kwargs)
  File "D:/Study/VMS/vipMangementSystem\vms\JWT.py", line 55, in __deco
    payload = jwt.decode(token, '1', algorithms=['HS256'])
  File "C:\Python27\lib\site-packages\jwt\api_jwt.py", line 93, in decode
    jwt, key=key, algorithms=algorithms, options=options, **kwargs
  File "C:\Python27\lib\site-packages\jwt\api_jws.py", line 157, in decode
    key, algorithms)
  File "C:\Python27\lib\site-packages\jwt\api_jws.py", line 224, in _verify_signature
    raise InvalidSignatureError('Signature verification failed')
InvalidSignatureError: Signature verification failed
2018-09-02 20:54:06,276 [exception:handle_uncaught_exception] [ERROR]- Internal Server Error: /delVipPerson/
Traceback (most recent call last):
  File "C:\Python27\lib\site-packages\django\core\handlers\exception.py", line 41, in inner
    response = get_response(request)
  File "C:\Python27\lib\site-packages\django\core\handlers\base.py", line 187, in _get_response
    response = self.process_exception_by_middleware(e, request)
  File "C:\Python27\lib\site-packages\django\core\handlers\base.py", line 185, in _get_response
    response = wrapped_callback(request, *callback_args, **callback_kwargs)
  File "D:/Study/VMS/vipMangementSystem\vms\JWT.py", line 55, in __deco
    payload = jwt.decode(token, 'mothanty', algorithms=['HS256'])
  File "C:\Python27\lib\site-packages\jwt\api_jwt.py", line 85, in decode
    payload, _, _, _ = self._load(jwt)
  File "C:\Python27\lib\site-packages\jwt\api_jws.py", line 178, in _load
    binary_type))
DecodeError: Invalid token type. Token must be a <type 'str'>
2018-09-02 22:25:55,657 [exception:handle_uncaught_exception] [ERROR]- Internal Server Error: /orderDetail/
Traceback (most recent call last):
  File "C:\Python27\lib\site-packages\django\core\handlers\exception.py", line 41, in inner
    response = get_response(request)
  File "C:\Python27\lib\site-packages\django\core\handlers\base.py", line 187, in _get_response
    response = self.process_exception_by_middleware(e, request)
  File "C:\Python27\lib\site-packages\django\core\handlers\base.py", line 185, in _get_response
    response = wrapped_callback(request, *callback_args, **callback_kwargs)
  File "D:\Study\VMS\vipMangementSystem\vms\JWT.py", line 59, in __deco
    payload = jwt.decode(token, 'mothanty', algorithms=['HS256'])
  File "C:\Python27\lib\site-packages\jwt\api_jwt.py", line 85, in decode
    payload, _, _, _ = self._load(jwt)
  File "C:\Python27\lib\site-packages\jwt\api_jws.py", line 184, in _load
    raise DecodeError('Not enough segments')
DecodeError: Not enough segments
2018-09-02 22:27:01,582 [exception:handle_uncaught_exception] [ERROR]- Internal Server Error: /orderDetail/
Traceback (most recent call last):
  File "C:\Python27\lib\site-packages\django\core\handlers\exception.py", line 41, in inner
    response = get_response(request)
  File "C:\Python27\lib\site-packages\django\core\handlers\base.py", line 187, in _get_response
    response = self.process_exception_by_middleware(e, request)
  File "C:\Python27\lib\site-packages\django\core\handlers\base.py", line 185, in _get_response
    response = wrapped_callback(request, *callback_args, **callback_kwargs)
  File "D:\Study\VMS\vipMangementSystem\vms\JWT.py", line 59, in __deco
    payload = jwt.decode(token, 'mothanty', algorithms=['HS256'])
  File "C:\Python27\lib\site-packages\jwt\api_jwt.py", line 85, in decode
    payload, _, _, _ = self._load(jwt)
  File "C:\Python27\lib\site-packages\jwt\api_jws.py", line 184, in _load
    raise DecodeError('Not enough segments')
DecodeError: Not enough segments
2018-09-03 00:10:32,823 [exception:handle_uncaught_exception] [ERROR]- Internal Server Error: /managerLogin/
Traceback (most recent call last):
  File "C:\Python27\lib\site-packages\django\core\handlers\exception.py", line 41, in inner
    response = get_response(request)
  File "C:\Python27\lib\site-packages\django\core\handlers\base.py", line 187, in _get_response
    response = self.process_exception_by_middleware(e, request)
  File "C:\Python27\lib\site-packages\django\core\handlers\base.py", line 185, in _get_response
    response = wrapped_callback(request, *callback_args, **callback_kwargs)
  File "D:/Study/VMS/vipMangementSystem\vms\views.py", line 993, in manager_login
    "INSERT INTO `vms`.`t_token`(`user_id`,`token`, `time`) VALUES (%s','%s', now());" %(result['id'],access_token) )
KeyError: u'id'
2018-09-03 00:34:26,066 [exception:handle_uncaught_exception] [ERROR]- Internal Server Error: /changePassword/
Traceback (most recent call last):
  File "C:\Python27\lib\site-packages\django\core\handlers\exception.py", line 41, in inner
    response = get_response(request)
  File "C:\Python27\lib\site-packages\django\core\handlers\base.py", line 187, in _get_response
    response = self.process_exception_by_middleware(e, request)
  File "C:\Python27\lib\site-packages\django\core\handlers\base.py", line 185, in _get_response
    response = wrapped_callback(request, *callback_args, **callback_kwargs)
  File "D:/Study/VMS/vipMangementSystem\vms\JWT.py", line 77, in __deco
    return func(request, *para, **kw)
  File "D:/Study/VMS/vipMangementSystem\vms\views.py", line 1068, in change_assword
    result = db.getOne("SELECT user_id FROM t_token WHERE token = '%s' AND password = '%s'"%(token,req.POST.get('oldPassword')))
  File "D:/Study/VMS/vipMangementSystem\vms\DB.py", line 264, in getOne
    count = self._cursor.execute(sql)
  File "C:\Python27\lib\site-packages\DBUtils\SteadyDB.py", line 661, in tough_method
    raise error  # reraise the original error again
OperationalError: (1054, "Unknown column 'password' in 'where clause'")
2018-09-09 17:21:14,526 [exception:handle_uncaught_exception] [ERROR]- Internal Server Error: /delOrder/
Traceback (most recent call last):
  File "C:\Python27\lib\site-packages\django\core\handlers\exception.py", line 41, in inner
    response = get_response(request)
  File "C:\Python27\lib\site-packages\django\core\handlers\base.py", line 187, in _get_response
    response = self.process_exception_by_middleware(e, request)
  File "C:\Python27\lib\site-packages\django\core\handlers\base.py", line 185, in _get_response
    response = wrapped_callback(request, *callback_args, **callback_kwargs)
  File "D:\Study\VMS\vipMangementSystem\vms\JWT.py", line 77, in __deco
    return func(request, *para, **kw)
  File "D:\Study\VMS\vipMangementSystem\vms\views.py", line 973, in del_order
    if count == 1:
NameError: global name 'count' is not defined
2018-09-09 17:31:33,161 [base:get_response] [WARNING]- Not Found: /favicon.ico
